Workbook

Sheet 目次
A1: 3. ジェンダー・ラベル
A2: =HYPERLINK('A1.年齢ごとジェンダー'!A1) -> 表A1：年齢層ごとのジェンダー・ラベル（%）
A3: =HYPERLINK('A2.ジェンダーごと年齢'!A1) -> 表A2：ジェンダー・ラベルごとの年齢（%）
A4: =HYPERLINK('A3.ジェンダーとラベル選択数'!A1) -> 表A3：ジェンダー・ラベルおよび年齢ごとの、選択されたジェンダー・ラベルの個数
A5: 4. 一人称代名詞
A6: =HYPERLINK('A4a.ジェンダーと一人称(選択式)'!A1) -> 表A4a：ジェンダー・ラベルごとの日本語一人称（選択式、%）
A7: =HYPERLINK('A4b.ジェンダーと一人称 (自由記入式)'!A1) -> 表A4b：ジェンダー・ラベルごとの日本語一人称（自由記入式, %）
A8: 5. 三人称代名詞
A9: =HYPERLINK('A5a.ジェンダーと三人称 (日,選択式)'!A1) -> 表A5a：ジェンダー・ラベルごとの日本語三人称（選択式, %）
A10: =HYPERLINK('A5b.ジェンダーと三人称 (日,記入式)'!A1) -> 表A5b：ジェンダー・ラベルごとの日本語三人称（記入式, %）
A11: =HYPERLINK('A6.ジェンダーと三人称 (英)'!A1) -> 表A6：ジェンダー・ラベルごとの英語三人称（英語を日常的に使う方, %）
A12: =HYPERLINK('A7.三人称（日）と三人称 (英)'!A1) -> 表A7：英語三人称ごとの、選択された日本語三人称（英語を日常的に使う方, %）
A13: 6. 敬称
A14: =HYPERLINK('A8.ジェンダーと敬称 (日)'!A1) -> 表A8：ジェンダー・ラベルごとの日本語敬称（%）
A15: =HYPERLINK('A9.ジェンダーと敬称 (英) '!A1) -> 表A9：ジェンダー・ラベルごとの英語敬称（英語を日常的に使う方, %）
A16: =HYPERLINK('A10.敬称（日）と敬称 (英)'!A1) -> 表A10：英語敬称ごとの選択された日本語敬称（英語を使う方, %）
A17: 7. 差別
A18: =HYPERLINK('A11.ジェンダーと差別(選択式)'!A1) -> 表A11：ジェンダー・ラベルごとの経験した、している、または不安である差別（ %）
A19: =HYPERLINK('A12.年齢層と差別(選択式)'!A1) -> 表A12：年齢層ごとの経験した、している、または不安である差別（ %）
A20: 8. トランジション
A21: =HYPERLINK('A13.ジェンダーとトランジション(希望+経験, 選択式)'!A1) -> 表A13：ジェンダー・ラベルごとの経験または希望しているトランジション（%）
A22: =HYPERLINK('A14.年齢層とトランジション(希望+経験, 選択式)'!A1) -> 表A14：年齢層ごとの経験または希望しているトランジション（%）
A23: =HYPERLINK('A15.ジェンダーとトランジション(経験,選択式) '!A1) -> 表A15：ジェンダー・ラベルごとの経験したトランジション（%）
A24: =HYPERLINK('A16.年齢層とトランジション(経験, 選択式)'!A1) -> 表A16：年齢層ごとの経験したトランジション（%）
A25: =HYPERLINK('A17.年齢層とトランジション(経験vs希望,選択式) '!A1) -> 表A17:年齢層ごとの「希望または経験しているトランジション」に対する「経験したトランジション」（%）
A28: =HYPERLINK('RAW (公開用)'!A1,"生データ") -> 生データ
A30: 計算用
A31: =HYPERLINK(集計用!A1, "集計用整形済みデータ") -> 集計用整形済みデータ
A32: =HYPERLINK(選んだジェンダー!A3, "選択されたジェンダー・ラベル") -> 選択されたジェンダー・ラベル

Sheet A1.年齢ごとジェンダー
A1: 表A1：年齢層ごとのジェンダー・ラベル（%）
A3: n= | B3: 年齢層 | C3: 全回答者 | D3: ノンバイナリー | E3: クィア／Queer | F3: Xジェンダー | G3: クエスチョニング | H3: 無性 | I3: （ジェンダー・）フルイド／（ジェンダー・）フリュイド／（ジェンダー・）フルイッド | J3: ジェンダークィア | K3: 不明／わからない | L3: Aジェンダー／エイジェンダー／アジェンダー／agender | M3: X | N3: 中性 | O3: トランスジェンダー | P3: 女性／woman | Q3: ノンバイナリー女性 | R3: 不定性 | S3: 無し | T3: トランス | U3: トランス*／trans* | V3: ジェンダー・ノンコンフォーミング／gender non-conforming | W3: ジェンダーレス | X3: 両性 | Y3: ニュートラル | Z3: ノンバイナリー男性 | AA3: 男性／man | AB3: enby／エンビー | AC3: レズビアン（ジェンダーについて） | AD3: シスジェンダー | AE3: デミガール | AF3: トランスマスキュリン | AG3: トランス男性 | AH3: デミジェンダー | AI3: バイジェンダー | AJ3: ゲイ（ジェンダーについて） | AK3: ジェンダーフラックス／フラックスジェンダー | AL3: トランスセクシュアル／transsexual | AM3: トランス女性 | AN3: デミAジェンダー | AO3: デミボーイ | AP3: トランスフェミニン | AQ3: 青年 | AR3: ポリジェンダー | AS3: フェム | AT3: ジェンダーヴォイド／gendervoid | AU3: ニューロジェンダー／neurogender | AV3: 女の子／girl | AW3: ゼノジェンダー／xenogender | AX3: バイナリー | AY3: 少年 | AZ3: ボイ | BA3: 男の子／boy | BB3: アンドロジャイン／androgyne | BC3: 少女 | BD3: ダイク／dyke | BE3: ブッチ／butch | BF3: おかま | BG3: ニューハーフ | BH3: おなべ
A4: =(COUNTA(集計用!$G:$G)-1) -> 443 | B4: 全回答者 | C4: =テーブル6[[#This Row],[n=]]/$A$4*100 -> 100 | D4: =(COUNTIF(集計用!$G:$G,"*, "&D3&",*"))/$A4*100 -> 57.78781 | E4: =(COUNTIF(集計用!$G:$G,"*, "&E3&",*"))/$A4*100 -> 32.505643 | F4: =(COUNTIF(集計用!$G:$G,"*, "&F3&",*"))/$A4*100 -> 27.31377 | G4: =(COUNTIF(集計用!$G:$G,"*, "&G3&",*"))/$A4*100 -> 19.413093 | H4: =(COUNTIF(集計用!$G:$G,"*, "&H3&",*"))/$A4*100 -> 19.413093 | I4: =(COUNTIF(集計用!$G:$G,"*, "&I3&",*"))/$A4*100 -> 16.930023 | J4: =(COUNTIF(集計用!$G:$G,"*, "&J3&",*"))/$A4*100 -> 16.704289 | K4: =(COUNTIF(集計用!$G:$G,"*, "&K3&",*"))/$A4*100 -> 16.027088 | ... BH4: =(COUNTIF(集計用!$G:$G,"*, "&BH3&",*"))/$A4*100 -> 0.22573363
A5: =(COUNTIFS(集計用!$AE:$AE,"11-15"))+(COUNTIFS(集計用!$AE:$AE,"16-20")) -> 49 | B5: -20 | C5: =テーブル6[[#This Row],[n=]]/$A$4*100 -> 11.060948 | D5: =(COUNTIFS(集計用!$G:$G,"*, "&D$3&",*", 集計用!$AE:$AE, "11-15")+COUNTIFS(集計用!$G:$G,"*, "&D$3&",*", 集計用!$AE:$AE, "16-20"))/$A5*100 -> 59.183673 | E5: =(COUNTIFS(集計用!$G:$G,"*, "&E$3&",*", 集計用!$AE:$AE, "11-15")+COUNTIFS(集計用!$G:$G,"*, "&E$3&",*", 集計用!$AE:$AE, "16-20"))/$A5*100 -> 28.571429 | F5: =(COUNTIFS(集計用!$G:$G,"*, "&F$3&",*", 集計用!$AE:$AE, "11-15")+COUNTIFS(集計用!$G:$G,"*, "&F$3&",*", 集計用!$AE:$AE, "16-20"))/$A5*100 -> 22.44898 | G5: =(COUNTIFS(集計用!$G:$G,"*, "&G$3&",*", 集計用!$AE:$AE, "11-15")+COUNTIFS(集計用!$G:$G,"*, "&G$3&",*", 集計用!$AE:$AE, "16-20"))/$A5*100 -> 20.408163 | H5: =(COUNTIFS(集計用!$G:$G,"*, "&H$3&",*", 集計用!$AE:$AE, "11-15")+COUNTIFS(集計用!$G:$G,"*, "&H$3&",*", 集計用!$AE:$AE, "16-20"))/$A5*100 -> 16.326531 | I5: =(COUNTIFS(集計用!$G:$G,"*, "&I$3&",*", 集計用!$AE:$AE, "11-15")+COUNTIFS(集計用!$G:$G,"*, "&I$3&",*", 集計用!$AE:$AE, "16-20"))/$A5*100 -> 12.244898 | J5: =(COUNTIFS(集計用!$G:$G,"*, "&J$3&",*", 集計用!$AE:$AE, "11-15")+COUNTIFS(集計用!$G:$G,"*, "&J$3&",*", 集計用!$AE:$AE, "16-20"))/$A5*100 -> 10.204082 | K5: =(COUNTIFS(集計用!$G:$G,"*, "&K$3&",*", 集計用!$AE:$AE, "11-15")+COUNTIFS(集計用!$G:$G,"*, "&K$3&",*", 集計用!$AE:$AE, "16-20"))/$A5*100 -> 16.326531 | ... BH5: =(COUNTIFS(集計用!$G:$G,"*, "&BH$3&",*", 集計用!$AE:$AE, "11-15")+COUNTIFS(集計用!$G:$G,"*, "&BH$3&",*", 集計用!$AE:$AE, "16-20"))/$A5*100 -> 0
A6: =(COUNTIFS(集計用!$AE:$AE,$B6)) -> 116 | B6: 21-25 | C6: =テーブル6[[#This Row],[n=]]/$A$4*100 -> 26.185102 | D6: =(COUNTIFS(集計用!$G:$G,"*, "&D$3&",*", 集計用!$AE:$AE, $B6))/$A6*100 -> 62.931034 | E6: =(COUNTIFS(集計用!$G:$G,"*, "&E$3&",*", 集計用!$AE:$AE, $B6))/$A6*100 -> 44.827586 | F6: =(COUNTIFS(集計用!$G:$G,"*, "&F$3&",*", 集計用!$AE:$AE, $B6))/$A6*100 -> 28.448276 | G6: =(COUNTIFS(集計用!$G:$G,"*, "&G$3&",*", 集計用!$AE:$AE, $B6))/$A6*100 -> 25 | H6: =(COUNTIFS(集計用!$G:$G,"*, "&H$3&",*", 集計用!$AE:$AE, $B6))/$A6*100 -> 18.103448 | I6: =(COUNTIFS(集計用!$G:$G,"*, "&I$3&",*", 集計用!$AE:$AE, $B6))/$A6*100 -> 23.275862 | J6: =(COUNTIFS(集計用!$G:$G,"*, "&J$3&",*", 集計用!$AE:$AE, $B6))/$A6*100 -> 23.275862 | K6: =(COUNTIFS(集計用!$G:$G,"*, "&K$3&",*", 集計用!$AE:$AE, $B6))/$A6*100 -> 18.965517 | ... BH6: =(COUNTIFS(集計用!$G:$G,"*, "&BH$3&",*", 集計用!$AE:$AE, $B6))/$A6*100 -> 0
A7: =(COUNTIFS(集計用!$AE:$AE,$B7)) -> 88 | B7: 26-30 | C7: =テーブル6[[#This Row],[n=]]/$A$4*100 -> 19.86456 | D7: =(COUNTIFS(集計用!$G:$G,"*, "&D$3&",*", 集計用!$AE:$AE, $B7))/$A7*100 -> 63.636364 | E7: =(COUNTIFS(集計用!$G:$G,"*, "&E$3&",*", 集計用!$AE:$AE, $B7))/$A7*100 -> 34.090909 | F7: =(COUNTIFS(集計用!$G:$G,"*, "&F$3&",*", 集計用!$AE:$AE, $B7))/$A7*100 -> 25 | G7: =(COUNTIFS(集計用!$G:$G,"*, "&G$3&",*", 集計用!$AE:$AE, $B7))/$A7*100 -> 19.318182 | H7: =(COUNTIFS(集計用!$G:$G,"*, "&H$3&",*", 集計用!$AE:$AE, $B7))/$A7*100 -> 22.727273 | I7: =(COUNTIFS(集計用!$G:$G,"*, "&I$3&",*", 集計用!$AE:$AE, $B7))/$A7*100 -> 19.318182 | J7: =(COUNTIFS(集計用!$G:$G,"*, "&J$3&",*", 集計用!$AE:$AE, $B7))/$A7*100 -> 13.636364 | K7: =(COUNTIFS(集計用!$G:$G,"*, "&K$3&",*", 集計用!$AE:$AE, $B7))/$A7*100 -> 19.318182 | ... BH7: =(COUNTIFS(集計用!$G:$G,"*, "&BH$3&",*", 集計用!$AE:$AE, $B7))/$A7*100 -> 1.1363636
A8: =(COUNTIFS(集計用!$AE:$AE,$B8)) -> 77 | B8: 31-35 | C8: =テーブル6[[#This Row],[n=]]/$A$4*100 -> 17.38149 | D8: =(COUNTIFS(集計用!$G:$G,"*, "&D$3&",*", 集計用!$AE:$AE, $B8))/$A8*100 -> 55.844156 | E8: =(COUNTIFS(集計用!$G:$G,"*, "&E$3&",*", 集計用!$AE:$AE, $B8))/$A8*100 -> 27.272727 | F8: =(COUNTIFS(集計用!$G:$G,"*, "&F$3&",*", 集計用!$AE:$AE, $B8))/$A8*100 -> 28.571429 | G8: =(COUNTIFS(集計用!$G:$G,"*, "&G$3&",*", 集計用!$AE:$AE, $B8))/$A8*100 -> 19.480519 | H8: =(COUNTIFS(集計用!$G:$G,"*, "&H$3&",*", 集計用!$AE:$AE, $B8))/$A8*100 -> 19.480519 | I8: =(COUNTIFS(集計用!$G:$G,"*, "&I$3&",*", 集計用!$AE:$AE, $B8))/$A8*100 -> 20.779221 | J8: =(COUNTIFS(集計用!$G:$G,"*, "&J$3&",*", 集計用!$AE:$AE, $B8))/$A8*100 -> 14.285714 | K8: =(COUNTIFS(集計用!$G:$G,"*, "&K$3&",*", 集計用!$AE:$AE, $B8))/$A8*100 -> 18.181818 | ... BH8: =(COUNTIFS(集計用!$G:$G,"*, "&BH$3&",*", 集計用!$AE:$AE, $B8))/$A8*100 -> 0
A9: =(COUNTIFS(集計用!$AE:$AE,$B9)) -> 34 | B9: 36-40 | C9: =テーブル6[[#This Row],[n=]]/$A$4*100 -> 7.6749436 | D9: =(COUNTIFS(集計用!$G:$G,"*, "&D$3&",*", 集計用!$AE:$AE, $B9))/$A9*100 -> 55.882353 | E9: =(COUNTIFS(集計用!$G:$G,"*, "&E$3&",*", 集計用!$AE:$AE, $B9))/$A9*100 -> 17.647059 | F9: =(COUNTIFS(集計用!$G:$G,"*, "&F$3&",*", 集計用!$AE:$AE, $B9))/$A9*100 -> 26.470588 | G9: =(COUNTIFS(集計用!$G:$G,"*, "&G$3&",*", 集計用!$AE:$AE, $B9))/$A9*100 -> 8.8235294 | H9: =(COUNTIFS(集計用!$G:$G,"*, "&H$3&",*", 集計用!$AE:$AE, $B9))/$A9*100 -> 29.411765 | I9: =(COUNTIFS(集計用!$G:$G,"*, "&I$3&",*", 集計用!$AE:$AE, $B9))/$A9*100 -> 5.8823529 | J9: =(COUNTIFS(集計用!$G:$G,"*, "&J$3&",*", 集計用!$AE:$AE, $B9))/$A9*100 -> 14.705882 | K9: =(COUNTIFS(集計用!$G:$G,"*, "&K$3&",*", 集計用!$AE:$AE, $B9))/$A9*100 -> 5.8823529 | ... BH9: =(COUNTIFS(集計用!$G:$G,"*, "&BH$3&",*", 集計用!$AE:$AE, $B9))/$A9*100 -> 0
A10: =(COUNTIFS(集計用!$AE:$AE,$B10)) -> 31 | B10: 41-45 | C10: =テーブル6[[#This Row],[n=]]/$A$4*100 -> 6.9977427 | D10: =(COUNTIFS(集計用!$G:$G,"*, "&D$3&",*", 集計用!$AE:$AE, $B10))/$A10*100 -> 51.612903 | E10: =(COUNTIFS(集計用!$G:$G,"*, "&E$3&",*", 集計用!$AE:$AE, $B10))/$A10*100 -> 25.806452 | F10: =(COUNTIFS(集計用!$G:$G,"*, "&F$3&",*", 集計用!$AE:$AE, $B10))/$A10*100 -> 38.709677 | G10: =(COUNTIFS(集計用!$G:$G,"*, "&G$3&",*", 集計用!$AE:$AE, $B10))/$A10*100 -> 12.903226 | H10: =(COUNTIFS(集計用!$G:$G,"*, "&H$3&",*", 集計用!$AE:$AE, $B10))/$A10*100 -> 9.6774194 | I10: =(COUNTIFS(集計用!$G:$G,"*, "&I$3&",*", 集計用!$AE:$AE, $B10))/$A10*100 -> 9.6774194 | J10: =(COUNTIFS(集計用!$G:$G,"*, "&J$3&",*", 集計用!$AE:$AE, $B10))/$A10*100 -> 19.354839 | K10: =(COUNTIFS(集計用!$G:$G,"*, "&K$3&",*", 集計用!$AE:$AE, $B10))/$A10*100 -> 6.4516129 | ... BH10: =(COUNTIFS(集計用!$G:$G,"*, "&BH$3&",*", 集計用!$AE:$AE, $B10))/$A10*100 -> 0
A11: =(COUNTIFS(集計用!$AE:$AE,$B11)) -> 24 | B11: 46-50 | C11: =テーブル6[[#This Row],[n=]]/$A$4*100 -> 5.4176072 | D11: =(COUNTIFS(集計用!$G:$G,"*, "&D$3&",*", 集計用!$AE:$AE, $B11))/$A11*100 -> 29.166667 | E11: =(COUNTIFS(集計用!$G:$G,"*, "&E$3&",*", 集計用!$AE:$AE, $B11))/$A11*100 -> 25 | F11: =(COUNTIFS(集計用!$G:$G,"*, "&F$3&",*", 集計用!$AE:$AE, $B11))/$A11*100 -> 20.833333 | G11: =(COUNTIFS(集計用!$G:$G,"*, "&G$3&",*", 集計用!$AE:$AE, $B11))/$A11*100 -> 0 | H11: =(COUNTIFS(集計用!$G:$G,"*, "&H$3&",*", 集計用!$AE:$AE, $B11))/$A11*100 -> 20.833333 | I11: =(COUNTIFS(集計用!$G:$G,"*, "&I$3&",*", 集計用!$AE:$AE, $B11))/$A11*100 -> 8.3333333 | J11: =(COUNTIFS(集計用!$G:$G,"*, "&J$3&",*", 集計用!$AE:$AE, $B11))/$A11*100 -> 12.5 | K11: =(COUNTIFS(集計用!$G:$G,"*, "&K$3&",*", 集計用!$AE:$AE, $B11))/$A11*100 -> 12.5 | ... BH11: =(COUNTIFS(集計用!$G:$G,"*, "&BH$3&",*", 集計用!$AE:$AE, $B11))/$A11*100 -> 0
A12: =(COUNTIFS(集計用!$AE:$AE,$B12)) -> 11 | B12: 51-55 | C12: =テーブル6[[#This Row],[n=]]/$A$4*100 -> 2.48307 | D12: =(COUNTIFS(集計用!$G:$G,"*, "&D$3&",*", 集計用!$AE:$AE, $B12))/$A12*100 -> 54.545455 | E12: =(COUNTIFS(集計用!$G:$G,"*, "&E$3&",*", 集計用!$AE:$AE, $B12))/$A12*100 -> 9.0909091 | F12: =(COUNTIFS(集計用!$G:$G,"*, "&F$3&",*", 集計用!$AE:$AE, $B12))/$A12*100 -> 27.272727 | G12: =(COUNTIFS(集計用!$G:$G,"*, "&G$3&",*", 集計用!$AE:$AE, $B12))/$A12*100 -> 36.363636 | H12: =(COUNTIFS(集計用!$G:$G,"*, "&H$3&",*", 集計用!$AE:$AE, $B12))/$A12*100 -> 18.181818 | I12: =(COUNTIFS(集計用!$G:$G,"*, "&I$3&",*", 集計用!$AE:$AE, $B12))/$A12*100 -> 0 | J12: =(COUNTIFS(集計用!$G:$G,"*, "&J$3&",*", 集計用!$AE:$AE, $B12))/$A12*100 -> 0 | K12: =(COUNTIFS(集計用!$G:$G,"*, "&K$3&",*", 集計用!$AE:$AE, $B12))/$A12*100 -> 18.181818 | ... BH12: =(COUNTIFS(集計用!$G:$G,"*, "&BH$3&",*", 集計用!$AE:$AE, $B12))/$A12*100 -> 0
A13: =(COUNTIFS(集計用!$AE:$AE,"61-65"))+(COUNTIFS(集計用!$AE:$AE,"56-60")) -> 12 | B13: 56+ | C13: =テーブル6[[#This Row],[n=]]/$A$4*100 -> 2.7088036 | D13: =(COUNTIFS(集計用!$G:$G,"*, "&D$3&",*", 集計用!$AE:$AE, "61-65")+COUNTIFS(集計用!$G:$G,"*, "&D$3&",*", 集計用!$AE:$AE, "56-60"))/$A13*100 -> 58.333333 | E13: =(COUNTIFS(集計用!$G:$G,"*, "&E$3&",*", 集計用!$AE:$AE, "61-65")+COUNTIFS(集計用!$G:$G,"*, "&E$3&",*", 集計用!$AE:$AE, "56-60"))/$A13*100 -> 50 | F13: =(COUNTIFS(集計用!$G:$G,"*, "&F$3&",*", 集計用!$AE:$AE, "61-65")+COUNTIFS(集計用!$G:$G,"*, "&F$3&",*", 集計用!$AE:$AE, "56-60"))/$A13*100 -> 33.333333 | G13: =(COUNTIFS(集計用!$G:$G,"*, "&G$3&",*", 集計用!$AE:$AE, "61-65")+COUNTIFS(集計用!$G:$G,"*, "&G$3&",*", 集計用!$AE:$AE, "56-60"))/$A13*100 -> 33.333333 | H13: =(COUNTIFS(集計用!$G:$G,"*, "&H$3&",*", 集計用!$AE:$AE, "61-65")+COUNTIFS(集計用!$G:$G,"*, "&H$3&",*", 集計用!$AE:$AE, "56-60"))/$A13*100 -> 16.666667 | I13: =(COUNTIFS(集計用!$G:$G,"*, "&I$3&",*", 集計用!$AE:$AE, "61-65")+COUNTIFS(集計用!$G:$G,"*, "&I$3&",*", 集計用!$AE:$AE, "56-60"))/$A13*100 -> 16.666667 | J13: =(COUNTIFS(集計用!$G:$G,"*, "&J$3&",*", 集計用!$AE:$AE, "61-65")+COUNTIFS(集計用!$G:$G,"*, "&J$3&",*", 集計用!$AE:$AE, "56-60"))/$A13*100 -> 41.666667 | K13: =(COUNTIFS(集計用!$G:$G,"*, "&K$3&",*", 集計用!$AE:$AE, "61-65")+COUNTIFS(集計用!$G:$G,"*, "&K$3&",*", 集計用!$AE:$AE, "56-60"))/$A13*100 -> 8.3333333 | ... BH13: =(COUNTIFS(集計用!$G:$G,"*, "&BH$3&",*", 集計用!$AE:$AE, "61-65")+COUNTIFS(集計用!$G:$G,"*, "&BH$3&",*", 集計用!$AE:$AE, "56-60"))/$A13*100 -> 0
A14: =(COUNTIFS(集計用!$AE:$AE,$B14)) -> 1 | B14: 無回答 | C14: =テーブル6[[#This Row],[n=]]/$A$4*100 -> 0.22573363 | D14: =(COUNTIFS(集計用!$G:$G,"*, "&D$3&",*", 集計用!$AE:$AE, $B14))/$A14*100 -> 0 | E14: =(COUNTIFS(集計用!$G:$G,"*, "&E$3&",*", 集計用!$AE:$AE, $B14))/$A14*100 -> 0 | F14: =(COUNTIFS(集計用!$G:$G,"*, "&F$3&",*", 集計用!$AE:$AE, $B14))/$A14*100 -> 0 | G14: =(COUNTIFS(集計用!$G:$G,"*, "&G$3&",*", 集計用!$AE:$AE, $B14))/$A14*100 -> 0 | H14: =(COUNTIFS(集計用!$G:$G,"*, "&H$3&",*", 集計用!$AE:$AE, $B14))/$A14*100 -> 0 | I14: =(COUNTIFS(集計用!$G:$G,"*, "&I$3&",*", 集計用!$AE:$AE, $B14))/$A14*100 -> 0 | J14: =(COUNTIFS(集計用!$G:$G,"*, "&J$3&",*", 集計用!$AE:$AE, $B14))/$A14*100 -> 0 | K14: =(COUNTIFS(集計用!$G:$G,"*, "&K$3&",*", 集計用!$AE:$AE, $B14))/$A14*100 -> 0 | ... BH14: =(COUNTIFS(集計用!$G:$G,"*, "&BH$3&",*", 集計用!$AE:$AE, $B14))/$A14*100 -> 0

Sheet A2.ジェンダーごと年齢
A1: 表A2：ジェンダー・ラベルごとの年齢（%）
A3: cluster | B3: n= | C3: ジェンダー・ラベル | D3: 全年齢層 | E3: -20 | F3: 21-25 | G3: 26-30 | H3: 31-35 | I3: 36-40 | J3: 41-45 | K3: 46-50 | L3: 51-55 | M3: 56+ | N3: 無回答
A4: 0 | B4: =(COUNTA(集計用!$G:$G)-1) -> 443 | C4: 全回答者 | D4: =テーブル2[[#This Row],[n=]]/443*100 -> 100 | E4: =(COUNTIFS(集計用!$AE:$AE,"11-15")+COUNTIFS(集計用!$AE:$AE,"16-20"))/テーブル2[[#This Row],[n=]]*100 -> 11.060948 | F4: =(COUNTIF(集計用!$AE:$AE,テーブル2[[#Headers],[21-25]]))/テーブル2[[#This Row],[n=]]*100 -> 26.185102 | G4: =(COUNTIF(集計用!$AE:$AE,テーブル2[[#Headers],[26-30]]))/テーブル2[[#This Row],[n=]]*100 -> 19.86456 | H4: =(COUNTIF(集計用!$AE:$AE,テーブル2[[#Headers],[31-35]]))/テーブル2[[#This Row],[n=]]*100 -> 17.38149 | I4: =(COUNTIF(集計用!$AE:$AE,テーブル2[[#Headers],[36-40]]))/テーブル2[[#This Row],[n=]]*100 -> 7.6749436 | J4: =(COUNTIF(集計用!$AE:$AE,テーブル2[[#Headers],[41-45]]))/テーブル2[[#This Row],[n=]]*100 -> 6.9977427 | K4: =(COUNTIF(集計用!$AE:$AE,テーブル2[[#Headers],[46-50]]))/テーブル2[[#This Row],[n=]]*100 -> 5.4176072 | L4: =(COUNTIF(集計用!$AE:$AE,テーブル2[[#Headers],[51-55]]))/テーブル2[[#This Row],[n=]]*100 -> 2.48307 | M4: =((COUNTIF(集計用!$AE:$AE,"56-60"))+(COUNTIF(集計用!$AE:$AE,"61-65")))/テーブル2[[#This Row],[n=]]*100 -> 2.7088036 | N4: =(COUNTIF(集計用!$AE:$AE,"無回答"))/テーブル2[[#This Row],[n=]]*100 -> 0.22573363
A5: 1 | B5: =(COUNTIFS(集計用!$G:$G,"*, "&$C5&",*")) -> 256 | C5: ノンバイナリー | D5: =テーブル2[[#This Row],[n=]]/443*100 -> 57.78781 | E5: =(COUNTIFS(集計用!$G:$G, "*, "&$C5&", *",集計用!$AE:$AE,"11-15")+COUNTIFS(集計用!$G:$G, "*, "&$C5&", *",集計用!$AE:$AE,"16-20"))/テーブル2[[#This Row],[n=]]*100 -> 11.328125 | F5: =(COUNTIFS(集計用!$G:$G, "*, "&$C5&", *",集計用!$AE:$AE,"21-25"))/テーブル2[[#This Row],[n=]]*100 -> 28.515625 | G5: =COUNTIFS(集計用!$G:$G, "*, "&$C5&", *",集計用!$AE:$AE,"26-30")/テーブル2[[#This Row],[n=]]*100 -> 21.875 | H5: =(COUNTIFS(集計用!$G:$G, "*, "&$C5&", *",集計用!$AE:$AE,"31-35"))/テーブル2[[#This Row],[n=]]*100 -> 16.796875 | I5: =(COUNTIFS(集計用!$G:$G, "*, "&$C5&", *",集計用!$AE:$AE,"36-40"))/テーブル2[[#This Row],[n=]]*100 -> 7.421875 | J5: =(COUNTIFS(集計用!$G:$G, "*, "&$C5&", *",集計用!$AE:$AE,"41-45"))/テーブル2[[#This Row],[n=]]*100 -> 6.25 | K5: =(COUNTIFS(集計用!$G:$G, "*, "&$C5&", *",集計用!$AE:$AE,"46-50"))/テーブル2[[#This Row],[n=]]*100 -> 2.734375 | L5: =(COUNTIFS(集計用!$G:$G, "*, "&$C5&", *",集計用!$AE:$AE,"51-55")+COUNTIFS(集計用!$G:$G, "*, "&$C5&", *",集計用!$AE:$AE,"56-60")+COUNTIFS(集計用!$G:$G, "*, "&$C5&", *",集計用!$AE:$AE,"61-65"))/テーブル2[[#This Row],[n=]]*100 -> 5.078125 | M5: =(COUNTIFS(集計用!$G:$G, "*, "&$C5&", *",集計用!$AE:$AE,"56-60")+COUNTIFS(集計用!$G:$G, "*, "&$C5&", *",集計用!$AE:$AE,"61-65"))/テーブル2[[#This Row],[n=]]*100 -> 2.734375 | N5: =COUNTIFS(集計用!$G:$G,"*, "&$C5&", *",集計用!$AE:$AE,"無回答")/テーブル2[[#This Row],[n=]]*100 -> 0
A6: 1 | B6: =(COUNTIFS(集計用!$G:$G,"*, "&$C6&",*")) -> 144 | C6: クィア／Queer | D6: =テーブル2[[#This Row],[n=]]/443*100 -> 32.505643 | E6: =(COUNTIFS(集計用!$G:$G, "*, "&$C6&", *",集計用!$AE:$AE,"11-15")+COUNTIFS(集計用!$G:$G, "*, "&$C6&", *",集計用!$AE:$AE,"16-20"))/テーブル2[[#This Row],[n=]]*100 -> 9.7222222 | F6: =(COUNTIFS(集計用!$G:$G, "*, "&$C6&", *",集計用!$AE:$AE,"21-25"))/テーブル2[[#This Row],[n=]]*100 -> 36.111111 | G6: =COUNTIFS(集計用!$G:$G, "*, "&$C6&", *",集計用!$AE:$AE,"26-30")/テーブル2[[#This Row],[n=]]*100 -> 20.833333 | H6: =(COUNTIFS(集計用!$G:$G, "*, "&$C6&", *",集計用!$AE:$AE,"31-35"))/テーブル2[[#This Row],[n=]]*100 -> 14.583333 | I6: =(COUNTIFS(集計用!$G:$G, "*, "&$C6&", *",集計用!$AE:$AE,"36-40"))/テーブル2[[#This Row],[n=]]*100 -> 4.1666667 | J6: =(COUNTIFS(集計用!$G:$G, "*, "&$C6&", *",集計用!$AE:$AE,"41-45"))/テーブル2[[#This Row],[n=]]*100 -> 5.5555556 | K6: =(COUNTIFS(集計用!$G:$G, "*, "&$C6&", *",集計用!$AE:$AE,"46-50"))/テーブル2[[#This Row],[n=]]*100 -> 4.1666667 | L6: =(COUNTIFS(集計用!$G:$G, "*, "&$C6&", *",集計用!$AE:$AE,"51-55")+COUNTIFS(集計用!$G:$G, "*, "&$C6&", *",集計用!$AE:$AE,"56-60")+COUNTIFS(集計用!$G:$G, "*, "&$C6&", *",集計用!$AE:$AE,"61-65"))/テーブル2[[#This Row],[n=]]*100 -> 4.8611111 | M6: =(COUNTIFS(集計用!$G:$G, "*, "&$C6&", *",集計用!$AE:$AE,"56-60")+COUNTIFS(集計用!$G:$G, "*, "&$C6&", *",集計用!$AE:$AE,"61-65"))/テーブル2[[#This Row],[n=]]*100 -> 4.1666667 | N6: =COUNTIFS(集計用!$G:$G,"*, "&$C6&", *",集計用!$AE:$AE,"無回答")/テーブル2[[#This Row],[n=]]*100 -> 0
A7: 2 | B7: =(COUNTIFS(集計用!$G:$G,"*, "&$C7&",*")) -> 121 | C7: Xジェンダー | D7: =テーブル2[[#This Row],[n=]]/443*100 -> 27.31377 | E7: =(COUNTIFS(集計用!$G:$G, "*, "&$C7&", *",集計用!$AE:$AE,"11-15")+COUNTIFS(集計用!$G:$G, "*, "&$C7&", *",集計用!$AE:$AE,"16-20"))/テーブル2[[#This Row],[n=]]*100 -> 9.0909091 | F7: =(COUNTIFS(集計用!$G:$G, "*, "&$C7&", *",集計用!$AE:$AE,"21-25"))/テーブル2[[#This Row],[n=]]*100 -> 27.272727 | G7: =COUNTIFS(集計用!$G:$G, "*, "&$C7&", *",集計用!$AE:$AE,"26-30")/テーブル2[[#This Row],[n=]]*100 -> 18.181818 | H7: =(COUNTIFS(集計用!$G:$G, "*, "&$C7&", *",集計用!$AE:$AE,"31-35"))/テーブル2[[#This Row],[n=]]*100 -> 18.181818 | I7: =(COUNTIFS(集計用!$G:$G, "*, "&$C7&", *",集計用!$AE:$AE,"36-40"))/テーブル2[[#This Row],[n=]]*100 -> 7.4380165 | J7: =(COUNTIFS(集計用!$G:$G, "*, "&$C7&", *",集計用!$AE:$AE,"41-45"))/テーブル2[[#This Row],[n=]]*100 -> 9.9173554 | K7: =(COUNTIFS(集計用!$G:$G, "*, "&$C7&", *",集計用!$AE:$AE,"46-50"))/テーブル2[[#This Row],[n=]]*100 -> 4.1322314 | L7: =(COUNTIFS(集計用!$G:$G, "*, "&$C7&", *",集計用!$AE:$AE,"51-55")+COUNTIFS(集計用!$G:$G, "*, "&$C7&", *",集計用!$AE:$AE,"56-60")+COUNTIFS(集計用!$G:$G, "*, "&$C7&", *",集計用!$AE:$AE,"61-65"))/テーブル2[[#This Row],[n=]]*100 -> 5.785124 | M7: =(COUNTIFS(集計用!$G:$G, "*, "&$C7&", *",集計用!$AE:$AE,"56-60")+COUNTIFS(集計用!$G:$G, "*, "&$C7&", *",集計用!$AE:$AE,"61-65"))/テーブル2[[#This Row],[n=]]*100 -> 3.3057851 | N7: =COUNTIFS(集計用!$G:$G,"*, "&$C7&", *",集計用!$AE:$AE,"無回答")/テーブル2[[#This Row],[n=]]*100 -> 0
A8: 1 | B8: =(COUNTIFS(集計用!$G:$G,"*, "&$C8&",*")) -> 86 | C8: クエスチョニング | D8: =テーブル2[[#This Row],[n=]]/443*100 -> 19.413093 | E8: =(COUNTIFS(集計用!$G:$G, "*, "&$C8&", *",集計用!$AE:$AE,"11-15")+COUNTIFS(集計用!$G:$G, "*, "&$C8&", *",集計用!$AE:$AE,"16-20"))/テーブル2[[#This Row],[n=]]*100 -> 11.627907 | F8: =(COUNTIFS(集計用!$G:$G, "*, "&$C8&", *",集計用!$AE:$AE,"21-25"))/テーブル2[[#This Row],[n=]]*100 -> 33.72093 | G8: =COUNTIFS(集計用!$G:$G, "*, "&$C8&", *",集計用!$AE:$AE,"26-30")/テーブル2[[#This Row],[n=]]*100 -> 19.767442 | H8: =(COUNTIFS(集計用!$G:$G, "*, "&$C8&", *",集計用!$AE:$AE,"31-35"))/テーブル2[[#This Row],[n=]]*100 -> 17.44186 | I8: =(COUNTIFS(集計用!$G:$G, "*, "&$C8&", *",集計用!$AE:$AE,"36-40"))/テーブル2[[#This Row],[n=]]*100 -> 3.4883721 | J8: =(COUNTIFS(集計用!$G:$G, "*, "&$C8&", *",集計用!$AE:$AE,"41-45"))/テーブル2[[#This Row],[n=]]*100 -> 4.6511628 | K8: =(COUNTIFS(集計用!$G:$G, "*, "&$C8&", *",集計用!$AE:$AE,"46-50"))/テーブル2[[#This Row],[n=]]*100 -> 0 | L8: =(COUNTIFS(集計用!$G:$G, "*, "&$C8&", *",集計用!$AE:$AE,"51-55")+COUNTIFS(集計用!$G:$G, "*, "&$C8&", *",集計用!$AE:$AE,"56-60")+COUNTIFS(集計用!$G:$G, "*, "&$C8&", *",集計用!$AE:$AE,"61-65"))/テーブル2[[#This Row],[n=]]*100 -> 9.3023256 | M8: =(COUNTIFS(集計用!$G:$G, "*, "&$C8&", *",集計用!$AE:$AE,"56-60")+COUNTIFS(集計用!$G:$G, "*, "&$C8&", *",集計用!$AE:$AE,"61-65"))/テーブル2[[#This Row],[n=]]*100 -> 4.6511628 | N8: =COUNTIFS(集計用!$G:$G,"*, "&$C8&", *",集計用!$AE:$AE,"無回答")/テーブル2[[#This Row],[n=]]*100 -> 0
A9: 3 | B9: =(COUNTIFS(集計用!$G:$G,"*, "&$C9&",*")) -> 86 | C9: 無性 | D9: =テーブル2[[#This Row],[n=]]/443*100 -> 19.413093 | E9: =(COUNTIFS(集計用!$G:$G, "*, "&$C9&", *",集計用!$AE:$AE,"11-15")+COUNTIFS(集計用!$G:$G, "*, "&$C9&", *",集計用!$AE:$AE,"16-20"))/テーブル2[[#This Row],[n=]]*100 -> 9.3023256 | F9: =(COUNTIFS(集計用!$G:$G, "*, "&$C9&", *",集計用!$AE:$AE,"21-25"))/テーブル2[[#This Row],[n=]]*100 -> 24.418605 | G9: =COUNTIFS(集計用!$G:$G, "*, "&$C9&", *",集計用!$AE:$AE,"26-30")/テーブル2[[#This Row],[n=]]*100 -> 23.255814 | H9: =(COUNTIFS(集計用!$G:$G, "*, "&$C9&", *",集計用!$AE:$AE,"31-35"))/テーブル2[[#This Row],[n=]]*100 -> 17.44186 | I9: =(COUNTIFS(集計用!$G:$G, "*, "&$C9&", *",集計用!$AE:$AE,"36-40"))/テーブル2[[#This Row],[n=]]*100 -> 11.627907 | J9: =(COUNTIFS(集計用!$G:$G, "*, "&$C9&", *",集計用!$AE:$AE,"41-45"))/テーブル2[[#This Row],[n=]]*100 -> 3.4883721 | K9: =(COUNTIFS(集計用!$G:$G, "*, "&$C9&", *",集計用!$AE:$AE,"46-50"))/テーブル2[[#This Row],[n=]]*100 -> 5.8139535 | L9: =(COUNTIFS(集計用!$G:$G, "*, "&$C9&", *",集計用!$AE:$AE,"51-55")+COUNTIFS(集計用!$G:$G, "*, "&$C9&", *",集計用!$AE:$AE,"56-60")+COUNTIFS(集計用!$G:$G, "*, "&$C9&", *",集計用!$AE:$AE,"61-65"))/テーブル2[[#This Row],[n=]]*100 -> 4.6511628 | M9: =(COUNTIFS(集計用!$G:$G, "*, "&$C9&", *",集計用!$AE:$AE,"56-60")+COUNTIFS(集計用!$G:$G, "*, "&$C9&", *",集計用!$AE:$AE,"61-65"))/テーブル2[[#This Row],[n=]]*100 -> 2.3255814 | N9: =COUNTIFS(集計用!$G:$G,"*, "&$C9&", *",集計用!$AE:$AE,"無回答")/テーブル2[[#This Row],[n=]]*100 -> 0
A10: 4 | B10: =(COUNTIFS(集計用!$G:$G,"*, "&$C10&",*")) -> 75 | C10: （ジェンダー・）フルイド／（ジェンダー・）フリュイド／（ジェンダー・）フルイッド | D10: =テーブル2[[#This Row],[n=]]/443*100 -> 16.930023 | E10: =(COUNTIFS(集計用!$G:$G, "*, "&$C10&", *",集計用!$AE:$AE,"11-15")+COUNTIFS(集計用!$G:$G, "*, "&$C10&", *",集計用!$AE:$AE,"16-20"))/テーブル2[[#This Row],[n=]]*100 -> 8 | F10: =(COUNTIFS(集計用!$G:$G, "*, "&$C10&", *",集計用!$AE:$AE,"21-25"))/テーブル2[[#This Row],[n=]]*100 -> 36 | G10: =COUNTIFS(集計用!$G:$G, "*, "&$C10&", *",集計用!$AE:$AE,"26-30")/テーブル2[[#This Row],[n=]]*100 -> 22.666667 | H10: =(COUNTIFS(集計用!$G:$G, "*, "&$C10&", *",集計用!$AE:$AE,"31-35"))/テーブル2[[#This Row],[n=]]*100 -> 21.333333 | I10: =(COUNTIFS(集計用!$G:$G, "*, "&$C10&", *",集計用!$AE:$AE,"36-40"))/テーブル2[[#This Row],[n=]]*100 -> 2.6666667 | J10: =(COUNTIFS(集計用!$G:$G, "*, "&$C10&", *",集計用!$AE:$AE,"41-45"))/テーブル2[[#This Row],[n=]]*100 -> 4 | K10: =(COUNTIFS(集計用!$G:$G, "*, "&$C10&", *",集計用!$AE:$AE,"46-50"))/テーブル2[[#This Row],[n=]]*100 -> 2.6666667 | L10: =(COUNTIFS(集計用!$G:$G, "*, "&$C10&", *",集計用!$AE:$AE,"51-55")+COUNTIFS(集計用!$G:$G, "*, "&$C10&", *",集計用!$AE:$AE,"56-60")+COUNTIFS(集計用!$G:$G, "*, "&$C10&", *",集計用!$AE:$AE,"61-65"))/テーブル2[[#This Row],[n=]]*100 -> 2.6666667 | M10: =(COUNTIFS(集計用!$G:$G, "*, "&$C10&", *",集計用!$AE:$AE,"56-60")+COUNTIFS(集計用!$G:$G, "*, "&$C10&", *",集計用!$AE:$AE,"61-65"))/テーブル2[[#This Row],[n=]]*100 -> 2.6666667 | N10: =COUNTIFS(集計用!$G:$G,"*, "&$C10&", *",集計用!$AE:$AE,"無回答")/テーブル2[[#This Row],[n=]]*100 -> 0
A11: 1 | B11: =(COUNTIFS(集計用!$G:$G,"*, "&$C11&",*")) -> 74 | C11: ジェンダークィア | D11: =テーブル2[[#This Row],[n=]]/443*100 -> 16.704289 | E11: =(COUNTIFS(集計用!$G:$G, "*, "&$C11&", *",集計用!$AE:$AE,"11-15")+COUNTIFS(集計用!$G:$G, "*, "&$C11&", *",集計用!$AE:$AE,"16-20"))/テーブル2[[#This Row],[n=]]*100 -> 6.7567568 | F11: =(COUNTIFS(集計用!$G:$G, "*, "&$C11&", *",集計用!$AE:$AE,"21-25"))/テーブル2[[#This Row],[n=]]*100 -> 36.486486 | G11: =COUNTIFS(集計用!$G:$G, "*, "&$C11&", *",集計用!$AE:$AE,"26-30")/テーブル2[[#This Row],[n=]]*100 -> 16.216216 | H11: =(COUNTIFS(集計用!$G:$G, "*, "&$C11&", *",集計用!$AE:$AE,"31-35"))/テーブル2[[#This Row],[n=]]*100 -> 14.864865 | I11: =(COUNTIFS(集計用!$G:$G, "*, "&$C11&", *",集計用!$AE:$AE,"36-40"))/テーブル2[[#This Row],[n=]]*100 -> 6.7567568 | J11: =(COUNTIFS(集計用!$G:$G, "*, "&$C11&", *",集計用!$AE:$AE,"41-45"))/テーブル2[[#This Row],[n=]]*100 -> 8.1081081 | K11: =(COUNTIFS(集計用!$G:$G, "*, "&$C11&", *",集計用!$AE:$AE,"46-50"))/テーブル2[[#This Row],[n=]]*100 -> 4.0540541 | L11: =(COUNTIFS(集計用!$G:$G, "*, "&$C11&", *",集計用!$AE:$AE,"51-55")+COUNTIFS(集計用!$G:$G, "*, "&$C11&", *",集計用!$AE:$AE,"56-60")+COUNTIFS(集計用!$G:$G, "*, "&$C11&", *",集計用!$AE:$AE,"61-65"))/テーブル2[[#This Row],[n=]]*100 -> 6.7567568 | M11: =(COUNTIFS(集計用!$G:$G, "*, "&$C11&", *",集計用!$AE:$AE,"56-60")+COUNTIFS(集計用!$G:$G, "*, "&$C11&", *",集計用!$AE:$AE,"61-65"))/テーブル2[[#This Row],[n=]]*100 -> 6.7567568 | N11: =COUNTIFS(集計用!$G:$G,"*, "&$C11&", *",集計用!$AE:$AE,"無回答")/テーブル2[[#This Row],[n=]]*100 -> 0
A12: 1 | B12: =(COUNTIFS(集計用!$G:$G,"*, "&$C12&",*")) -> 71 | C12: 不明／わからない | D12: =テーブル2[[#This Row],[n=]]/443*100 -> 16.027088 | E12: =(COUNTIFS(集計用!$G:$G, "*, "&$C12&", *",集計用!$AE:$AE,"11-15")+COUNTIFS(集計用!$G:$G, "*, "&$C12&", *",集計用!$AE:$AE,"16-20"))/テーブル2[[#This Row],[n=]]*100 -> 11.267606 | F12: =(COUNTIFS(集計用!$G:$G, "*, "&$C12&", *",集計用!$AE:$AE,"21-25"))/テーブル2[[#This Row],[n=]]*100 -> 30.985915 | G12: =COUNTIFS(集計用!$G:$G, "*, "&$C12&", *",集計用!$AE:$AE,"26-30")/テーブル2[[#This Row],[n=]]*100 -> 23.943662 | H12: =(COUNTIFS(集計用!$G:$G, "*, "&$C12&", *",集計用!$AE:$AE,"31-35"))/テーブル2[[#This Row],[n=]]*100 -> 19.71831 | I12: =(COUNTIFS(集計用!$G:$G, "*, "&$C12&", *",集計用!$AE:$AE,"36-40"))/テーブル2[[#This Row],[n=]]*100 -> 2.8169014 | J12: =(COUNTIFS(集計用!$G:$G, "*, "&$C12&", *",集計用!$AE:$AE,"41-45"))/テーブル2[[#This Row],[n=]]*100 -> 2.8169014 | K12: =(COUNTIFS(集計用!$G:$G, "*, "&$C12&", *",集計用!$AE:$AE,"46-50"))/テーブル2[[#This Row],[n=]]*100 -> 4.2253521 | L12: =(COUNTIFS(集計用!$G:$G, "*, "&$C12&", *",集計用!$AE:$AE,"51-55")+COUNTIFS(集計用!$G:$G, "*, "&$C12&", *",集計用!$AE:$AE,"56-60")+COUNTIFS(集計用!$G:$G, "*, "&$C12&", *",集計用!$AE:$AE,"61-65"))/テーブル2[[#This Row],[n=]]*100 -> 4.2253521 | M12: =(COUNTIFS(集計用!$G:$G, "*, "&$C12&", *",集計用!$AE:$AE,"56-60")+COUNTIFS(集計用!$G:$G, "*, "&$C12&", *",集計用!$AE:$AE,"61-65"))/テーブル2[[#This Row],[n=]]*100 -> 1.4084507 | N12: =COUNTIFS(集計用!$G:$G,"*, "&$C12&", *",集計用!$AE:$AE,"無回答")/テーブル2[[#This Row],[n=]]*100 -> 0
A13: 3 | B13: =(COUNTIFS(集計用!$G:$G,"*, "&$C13&",*")) -> 71 | C13: Aジェンダー／エイジェンダー／アジェンダー／agender | D13: =テーブル2[[#This Row],[n=]]/443*100 -> 16.027088 | E13: =(COUNTIFS(集計用!$G:$G, "*, "&$C13&", *",集計用!$AE:$AE,"11-15")+COUNTIFS(集計用!$G:$G, "*, "&$C13&", *",集計用!$AE:$AE,"16-20"))/テーブル2[[#This Row],[n=]]*100 -> 11.267606 | F13: =(COUNTIFS(集計用!$G:$G, "*, "&$C13&", *",集計用!$AE:$AE,"21-25"))/テーブル2[[#This Row],[n=]]*100 -> 28.169014 | G13: =COUNTIFS(集計用!$G:$G, "*, "&$C13&", *",集計用!$AE:$AE,"26-30")/テーブル2[[#This Row],[n=]]*100 -> 21.126761 | H13: =(COUNTIFS(集計用!$G:$G, "*, "&$C13&", *",集計用!$AE:$AE,"31-35"))/テーブル2[[#This Row],[n=]]*100 -> 18.309859 | I13: =(COUNTIFS(集計用!$G:$G, "*, "&$C13&", *",集計用!$AE:$AE,"36-40"))/テーブル2[[#This Row],[n=]]*100 -> 8.4507042 | J13: =(COUNTIFS(集計用!$G:$G, "*, "&$C13&", *",集計用!$AE:$AE,"41-45"))/テーブル2[[#This Row],[n=]]*100 -> 5.6338028 | K13: =(COUNTIFS(集計用!$G:$G, "*, "&$C13&", *",集計用!$AE:$AE,"46-50"))/テーブル2[[#This Row],[n=]]*100 -> 1.4084507 | L13: =(COUNTIFS(集計用!$G:$G, "*, "&$C13&", *",集計用!$AE:$AE,"51-55")+COUNTIFS(集計用!$G:$G, "*, "&$C13&", *",集計用!$AE:$AE,"56-60")+COUNTIFS(集計用!$G:$G, "*, "&$C13&", *",集計用!$AE:$AE,"61-65"))/テーブル2[[#This Row],[n=]]*100 -> 5.6338028 | M13: =(COUNTIFS(集計用!$G:$G, "*, "&$C13&", *",集計用!$AE:$AE,"56-60")+COUNTIFS(集計用!$G:$G, "*, "&$C13&", *",集計用!$AE:$AE,"61-65"))/テーブル2[[#This Row],[n=]]*100 -> 1.4084507 | N13: =COUNTIFS(集計用!$G:$G,"*, "&$C13&", *",集計用!$AE:$AE,"無回答")/テーブル2[[#This Row],[n=]]*100 -> 0
A14: 2 | B14: =(COUNTIFS(集計用!$G:$G,"*, "&$C14&",*")) -> 69 | C14: X | D14: =テーブル2[[#This Row],[n=]]/443*100 -> 15.575621 | E14: =(COUNTIFS(集計用!$G:$G, "*, "&$C14&", *",集計用!$AE:$AE,"11-15")+COUNTIFS(集計用!$G:$G, "*, "&$C14&", *",集計用!$AE:$AE,"16-20"))/テーブル2[[#This Row],[n=]]*100 -> 7.2463768 | F14: =(COUNTIFS(集計用!$G:$G, "*, "&$C14&", *",集計用!$AE:$AE,"21-25"))/テーブル2[[#This Row],[n=]]*100 -> 23.188406 | G14: =COUNTIFS(集計用!$G:$G, "*, "&$C14&", *",集計用!$AE:$AE,"26-30")/テーブル2[[#This Row],[n=]]*100 -> 23.188406 | H14: =(COUNTIFS(集計用!$G:$G, "*, "&$C14&", *",集計用!$AE:$AE,"31-35"))/テーブル2[[#This Row],[n=]]*100 -> 18.84058 | I14: =(COUNTIFS(集計用!$G:$G, "*, "&$C14&", *",集計用!$AE:$AE,"36-40"))/テーブル2[[#This Row],[n=]]*100 -> 8.6956522 | J14: =(COUNTIFS(集計用!$G:$G, "*, "&$C14&", *",集計用!$AE:$AE,"41-45"))/テーブル2[[#This Row],[n=]]*100 -> 8.6956522 | K14: =(COUNTIFS(集計用!$G:$G, "*, "&$C14&", *",集計用!$AE:$AE,"46-50"))/テーブル2[[#This Row],[n=]]*100 -> 5.7971014 | L14: =(COUNTIFS(集計用!$G:$G, "*, "&$C14&", *",集計用!$AE:$AE,"51-55")+COUNTIFS(集計用!$G:$G, "*, "&$C14&", *",集計用!$AE:$AE,"56-60")+COUNTIFS(集計用!$G:$G, "*, "&$C14&", *",集計用!$AE:$AE,"61-65"))/テーブル2[[#This Row],[n=]]*100 -> 2.8985507 | M14: =(COUNTIFS(集計用!$G:$G, "*, "&$C14&", *",集計用!$AE:$AE,"56-60")+COUNTIFS(集計用!$G:$G, "*, "&$C14&", *",集計用!$AE:$AE,"61-65"))/テーブル2[[#This Row],[n=]]*100 -> 2.8985507 | N14: =COUNTIFS(集計用!$G:$G,"*, "&$C14&", *",集計用!$AE:$AE,"無回答")/テーブル2[[#This Row],[n=]]*100 -> 1.4492754
A15: 5 | B15: =(COUNTIFS(集計用!$G:$G,"*, "&$C15&",*")) -> 60 | C15: トランスジェンダー | D15: =テーブル2[[#This Row],[n=]]/443*100 -> 13.544018 | E15: =(COUNTIFS(集計用!$G:$G, "*, "&$C15&", *",集計用!$AE:$AE,"11-15")+COUNTIFS(集計用!$G:$G, "*, "&$C15&", *",集計用!$AE:$AE,"16-20"))/テーブル2[[#This Row],[n=]]*100 -> 6.6666667 | F15: =(COUNTIFS(集計用!$G:$G, "*, "&$C15&", *",集計用!$AE:$AE,"21-25"))/テーブル2[[#This Row],[n=]]*100 -> 21.666667 | G15: =COUNTIFS(集計用!$G:$G, "*, "&$C15&", *",集計用!$AE:$AE,"26-30")/テーブル2[[#This Row],[n=]]*100 -> 25 | H15: =(COUNTIFS(集計用!$G:$G, "*, "&$C15&", *",集計用!$AE:$AE,"31-35"))/テーブル2[[#This Row],[n=]]*100 -> 15 | I15: =(COUNTIFS(集計用!$G:$G, "*, "&$C15&", *",集計用!$AE:$AE,"36-40"))/テーブル2[[#This Row],[n=]]*100 -> 6.6666667 | J15: =(COUNTIFS(集計用!$G:$G, "*, "&$C15&", *",集計用!$AE:$AE,"41-45"))/テーブル2[[#This Row],[n=]]*100 -> 8.3333333 | K15: =(COUNTIFS(集計用!$G:$G, "*, "&$C15&", *",集計用!$AE:$AE,"46-50"))/テーブル2[[#This Row],[n=]]*100 -> 6.6666667 | L15: =(COUNTIFS(集計用!$G:$G, "*, "&$C15&", *",集計用!$AE:$AE,"51-55")+COUNTIFS(集計用!$G:$G, "*, "&$C15&", *",集計用!$AE:$AE,"56-60")+COUNTIFS(集計用!$G:$G, "*, "&$C15&", *",集計用!$AE:$AE,"61-65"))/テーブル2[[#This Row],[n=]]*100 -> 10 | M15: =(COUNTIFS(集計用!$G:$G, "*, "&$C15&", *",集計用!$AE:$AE,"56-60")+COUNTIFS(集計用!$G:$G, "*, "&$C15&", *",集計用!$AE:$AE,"61-65"))/テーブル2[[#This Row],[n=]]*100 -> 6.6666667 | N15: =COUNTIFS(集計用!$G:$G,"*, "&$C15&", *",集計用!$AE:$AE,"無回答")/テーブル2[[#This Row],[n=]]*100 -> 0
A16: 2 | B16: =(COUNTIFS(集計用!$G:$G,"*, "&$C16&",*")) -> 60 | C16: 中性 | D16: =テーブル2[[#This Row],[n=]]/443*100 -> 13.544018 | E16: =(COUNTIFS(集計用!$G:$G, "*, "&$C16&", *",集計用!$AE:$AE,"11-15")+COUNTIFS(集計用!$G:$G, "*, "&$C16&", *",集計用!$AE:$AE,"16-20"))/テーブル2[[#This Row],[n=]]*100 -> 3.3333333 | F16: =(COUNTIFS(集計用!$G:$G, "*, "&$C16&", *",集計用!$AE:$AE,"21-25"))/テーブル2[[#This Row],[n=]]*100 -> 21.666667 | G16: =COUNTIFS(集計用!$G:$G, "*, "&$C16&", *",集計用!$AE:$AE,"26-30")/テーブル2[[#This Row],[n=]]*100 -> 25 | H16: =(COUNTIFS(集計用!$G:$G, "*, "&$C16&", *",集計用!$AE:$AE,"31-35"))/テーブル2[[#This Row],[n=]]*100 -> 15 | I16: =(COUNTIFS(集計用!$G:$G, "*, "&$C16&", *",集計用!$AE:$AE,"36-40"))/テーブル2[[#This Row],[n=]]*100 -> 8.3333333 | J16: =(COUNTIFS(集計用!$G:$G, "*, "&$C16&", *",集計用!$AE:$AE,"41-45"))/テーブル2[[#This Row],[n=]]*100 -> 13.333333 | K16: =(COUNTIFS(集計用!$G:$G, "*, "&$C16&", *",集計用!$AE:$AE,"46-50"))/テーブル2[[#This Row],[n=]]*100 -> 8.3333333 | L16: =(COUNTIFS(集計用!$G:$G, "*, "&$C16&", *",集計用!$AE:$AE,"51-55")+COUNTIFS(集計用!$G:$G, "*, "&$C16&", *",集計用!$AE:$AE,"56-60")+COUNTIFS(集計用!$G:$G, "*, "&$C16&", *",集計用!$AE:$AE,"61-65"))/テーブル2[[#This Row],[n=]]*100 -> 5 | M16: =(COUNTIFS(集計用!$G:$G, "*, "&$C16&", *",集計用!$AE:$AE,"56-60")+COUNTIFS(集計用!$G:$G, "*, "&$C16&", *",集計用!$AE:$AE,"61-65"))/テーブル2[[#This Row],[n=]]*100 -> 5 | N16: =COUNTIFS(集計用!$G:$G,"*, "&$C16&", *",集計用!$AE:$AE,"無回答")/テーブル2[[#This Row],[n=]]*100 -> 0
... A56: 4 | B56: =(COUNTIFS(集計用!$G:$G,"*, "&$C56&",*")) -> 5 | C56: 少女 | D56: =テーブル2[[#This Row],[n=]]/443*100 -> 1.1286682 | E56: =(COUNTIFS(集計用!$G:$G, "*, "&$C56&", *",集計用!$AE:$AE,"11-15")+COUNTIFS(集計用!$G:$G, "*, "&$C56&", *",集計用!$AE:$AE,"16-20"))/テーブル2[[#This Row],[n=]]*100 -> 40 | F56: =(COUNTIFS(集計用!$G:$G, "*, "&$C56&", *",集計用!$AE:$AE,"21-25"))/テーブル2[[#This Row],[n=]]*100 -> 20 | G56: =COUNTIFS(集計用!$G:$G, "*, "&$C56&", *",集計用!$AE:$AE,"26-30")/テーブル2[[#This Row],[n=]]*100 -> 20 | H56: =(COUNTIFS(集計用!$G:$G, "*, "&$C56&", *",集計用!$AE:$AE,"31-35"))/テーブル2[[#This Row],[n=]]*100 -> 20 | I56: =(COUNTIFS(集計用!$G:$G, "*, "&$C56&", *",集計用!$AE:$AE,"36-40"))/テーブル2[[#This Row],[n=]]*100 -> 0 | J56: =(COUNTIFS(集計用!$G:$G, "*, "&$C56&", *",集計用!$AE:$AE,"41-45"))/テーブル2[[#This Row],[n=]]*100 -> 0 | K56: =(COUNTIFS(集計用!$G:$G, "*, "&$C56&", *",集計用!$AE:$AE,"46-50"))/テーブル2[[#This Row],[n=]]*100 -> 0 | L56: =(COUNTIFS(集計用!$G:$G, "*, "&$C56&", *",集計用!$AE:$AE,"51-55")+COUNTIFS(集計用!$G:$G, "*, "&$C56&", *",集計用!$AE:$AE,"56-60")+COUNTIFS(集計用!$G:$G, "*, "&$C56&", *",集計用!$AE:$AE,"61-65"))/テーブル2[[#This Row],[n=]]*100 -> 0 | M56: =(COUNTIFS(集計用!$G:$G, "*, "&$C56&", *",集計用!$AE:$AE,"56-60")+COUNTIFS(集計用!$G:$G, "*, "&$C56&", *",集計用!$AE:$AE,"61-65"))/テーブル2[[#This Row],[n=]]*100 -> 0 | N56: =COUNTIFS(集計用!$G:$G,"*, "&$C56&", *",集計用!$AE:$AE,"無回答")/テーブル2[[#This Row],[n=]]*100 -> 0
A57: NA | B57: =(COUNTIFS(集計用!$G:$G,"*, "&$C57&",*")) -> 4 | C57: ダイク／dyke | D57: =テーブル2[[#This Row],[n=]]/443*100 -> 0.90293454 | E57: =(COUNTIFS(集計用!$G:$G, "*, "&$C57&", *",集計用!$AE:$AE,"11-15")+COUNTIFS(集計用!$G:$G, "*, "&$C57&", *",集計用!$AE:$AE,"16-20"))/テーブル2[[#This Row],[n=]]*100 -> 25 | F57: =(COUNTIFS(集計用!$G:$G, "*, "&$C57&", *",集計用!$AE:$AE,"21-25"))/テーブル2[[#This Row],[n=]]*100 -> 50 | G57: =COUNTIFS(集計用!$G:$G, "*, "&$C57&", *",集計用!$AE:$AE,"26-30")/テーブル2[[#This Row],[n=]]*100 -> 0 | H57: =(COUNTIFS(集計用!$G:$G, "*, "&$C57&", *",集計用!$AE:$AE,"31-35"))/テーブル2[[#This Row],[n=]]*100 -> 0 | I57: =(COUNTIFS(集計用!$G:$G, "*, "&$C57&", *",集計用!$AE:$AE,"36-40"))/テーブル2[[#This Row],[n=]]*100 -> 0 | J57: =(COUNTIFS(集計用!$G:$G, "*, "&$C57&", *",集計用!$AE:$AE,"41-45"))/テーブル2[[#This Row],[n=]]*100 -> 0 | K57: =(COUNTIFS(集計用!$G:$G, "*, "&$C57&", *",集計用!$AE:$AE,"46-50"))/テーブル2[[#This Row],[n=]]*100 -> 25 | L57: =(COUNTIFS(集計用!$G:$G, "*, "&$C57&", *",集計用!$AE:$AE,"51-55")+COUNTIFS(集計用!$G:$G, "*, "&$C57&", *",集計用!$AE:$AE,"56-60")+COUNTIFS(集計用!$G:$G, "*, "&$C57&", *",集計用!$AE:$AE,"61-65"))/テーブル2[[#This Row],[n=]]*100 -> 0 | M57: =(COUNTIFS(集計用!$G:$G, "*, "&$C57&", *",集計用!$AE:$AE,"56-60")+COUNTIFS(集計用!$G:$G, "*, "&$C57&", *",集計用!$AE:$AE,"61-65"))/テーブル2[[#This Row],[n=]]*100 -> 0 | N57: =COUNTIFS(集計用!$G:$G,"*, "&$C57&", *",集計用!$AE:$AE,"無回答")/テーブル2[[#This Row],[n=]]*100 -> 0
A58: NA | B58: =(COUNTIFS(集計用!$G:$G,"*, "&$C58&",*")) -> 4 | C58: ブッチ／butch | D58: =テーブル2[[#This Row],[n=]]/443*100 -> 0.90293454 | E58: =(COUNTIFS(集計用!$G:$G, "*, "&$C58&", *",集計用!$AE:$AE,"11-15")+COUNTIFS(集計用!$G:$G, "*, "&$C58&", *",集計用!$AE:$AE,"16-20"))/テーブル2[[#This Row],[n=]]*100 -> 25 | F58: =(COUNTIFS(集計用!$G:$G, "*, "&$C58&", *",集計用!$AE:$AE,"21-25"))/テーブル2[[#This Row],[n=]]*100 -> 75 | G58: =COUNTIFS(集計用!$G:$G, "*, "&$C58&", *",集計用!$AE:$AE,"26-30")/テーブル2[[#This Row],[n=]]*100 -> 0 | H58: =(COUNTIFS(集計用!$G:$G, "*, "&$C58&", *",集計用!$AE:$AE,"31-35"))/テーブル2[[#This Row],[n=]]*100 -> 0 | I58: =(COUNTIFS(集計用!$G:$G, "*, "&$C58&", *",集計用!$AE:$AE,"36-40"))/テーブル2[[#This Row],[n=]]*100 -> 0 | J58: =(COUNTIFS(集計用!$G:$G, "*, "&$C58&", *",集計用!$AE:$AE,"41-45"))/テーブル2[[#This Row],[n=]]*100 -> 0 | K58: =(COUNTIFS(集計用!$G:$G, "*, "&$C58&", *",集計用!$AE:$AE,"46-50"))/テーブル2[[#This Row],[n=]]*100 -> 0 | L58: =(COUNTIFS(集計用!$G:$G, "*, "&$C58&", *",集計用!$AE:$AE,"51-55")+COUNTIFS(集計用!$G:$G, "*, "&$C58&", *",集計用!$AE:$AE,"56-60")+COUNTIFS(集計用!$G:$G, "*, "&$C58&", *",集計用!$AE:$AE,"61-65"))/テーブル2[[#This Row],[n=]]*100 -> 0 | M58: =(COUNTIFS(集計用!$G:$G, "*, "&$C58&", *",集計用!$AE:$AE,"56-60")+COUNTIFS(集計用!$G:$G, "*, "&$C58&", *",集計用!$AE:$AE,"61-65"))/テーブル2[[#This Row],[n=]]*100 -> 0 | N58: =COUNTIFS(集計用!$G:$G,"*, "&$C58&", *",集計用!$AE:$AE,"無回答")/テーブル2[[#This Row],[n=]]*100 -> 0
A59: NA | B59: =(COUNTIFS(集計用!$G:$G,"*, "&$C59&",*")) -> 3 | C59: おかま | D59: =テーブル2[[#This Row],[n=]]/443*100 -> 0.6772009 | E59: =(COUNTIFS(集計用!$G:$G, "*, "&$C59&", *",集計用!$AE:$AE,"11-15")+COUNTIFS(集計用!$G:$G, "*, "&$C59&", *",集計用!$AE:$AE,"16-20"))/テーブル2[[#This Row],[n=]]*100 -> 0 | F59: =(COUNTIFS(集計用!$G:$G, "*, "&$C59&", *",集計用!$AE:$AE,"21-25"))/テーブル2[[#This Row],[n=]]*100 -> 33.333333 | G59: =COUNTIFS(集計用!$G:$G, "*, "&$C59&", *",集計用!$AE:$AE,"26-30")/テーブル2[[#This Row],[n=]]*100 -> 33.333333 | H59: =(COUNTIFS(集計用!$G:$G, "*, "&$C59&", *",集計用!$AE:$AE,"31-35"))/テーブル2[[#This Row],[n=]]*100 -> 0 | I59: =(COUNTIFS(集計用!$G:$G, "*, "&$C59&", *",集計用!$AE:$AE,"36-40"))/テーブル2[[#This Row],[n=]]*100 -> 33.333333 | J59: =(COUNTIFS(集計用!$G:$G, "*, "&$C59&", *",集計用!$AE:$AE,"41-45"))/テーブル2[[#This Row],[n=]]*100 -> 0 | K59: =(COUNTIFS(集計用!$G:$G, "*, "&$C59&", *",集計用!$AE:$AE,"46-50"))/テーブル2[[#This Row],[n=]]*100 -> 0 | L59: =(COUNTIFS(集計用!$G:$G, "*, "&$C59&", *",集計用!$AE:$AE,"51-55")+COUNTIFS(集計用!$G:$G, "*, "&$C59&", *",集計用!$AE:$AE,"56-60")+COUNTIFS(集計用!$G:$G, "*, "&$C59&", *",集計用!$AE:$AE,"61-65"))/テーブル2[[#This Row],[n=]]*100 -> 0 | M59: =(COUNTIFS(集計用!$G:$G, "*, "&$C59&", *",集計用!$AE:$AE,"56-60")+COUNTIFS(集計用!$G:$G, "*, "&$C59&", *",集計用!$AE:$AE,"61-65"))/テーブル2[[#This Row],[n=]]*100 -> 0 | N59: =COUNTIFS(集計用!$G:$G,"*, "&$C59&", *",集計用!$AE:$AE,"無回答")/テーブル2[[#This Row],[n=]]*100 -> 0
A60: NA | B60: =(COUNTIFS(集計用!$G:$G,"*, "&$C60&",*")) -> 2 | C60: ニューハーフ | D60: =テーブル2[[#This Row],[n=]]/443*100 -> 0.45146727 | E60: =(COUNTIFS(集計用!$G:$G, "*, "&$C60&", *",集計用!$AE:$AE,"11-15")+COUNTIFS(集計用!$G:$G, "*, "&$C60&", *",集計用!$AE:$AE,"16-20"))/テーブル2[[#This Row],[n=]]*100 -> 0 | F60: =(COUNTIFS(集計用!$G:$G, "*, "&$C60&", *",集計用!$AE:$AE,"21-25"))/テーブル2[[#This Row],[n=]]*100 -> 50 | G60: =COUNTIFS(集計用!$G:$G, "*, "&$C60&", *",集計用!$AE:$AE,"26-30")/テーブル2[[#This Row],[n=]]*100 -> 0 | H60: =(COUNTIFS(集計用!$G:$G, "*, "&$C60&", *",集計用!$AE:$AE,"31-35"))/テーブル2[[#This Row],[n=]]*100 -> 0 | I60: =(COUNTIFS(集計用!$G:$G, "*, "&$C60&", *",集計用!$AE:$AE,"36-40"))/テーブル2[[#This Row],[n=]]*100 -> 0 | J60: =(COUNTIFS(集計用!$G:$G, "*, "&$C60&", *",集計用!$AE:$AE,"41-45"))/テーブル2[[#This Row],[n=]]*100 -> 0 | K60: =(COUNTIFS(集計用!$G:$G, "*, "&$C60&", *",集計用!$AE:$AE,"46-50"))/テーブル2[[#This Row],[n=]]*100 -> 50 | L60: =(COUNTIFS(集計用!$G:$G, "*, "&$C60&", *",集計用!$AE:$AE,"51-55")+COUNTIFS(集計用!$G:$G, "*, "&$C60&", *",集計用!$AE:$AE,"56-60")+COUNTIFS(集計用!$G:$G, "*, "&$C60&", *",集計用!$AE:$AE,"61-65"))/テーブル2[[#This Row],[n=]]*100 -> 0 | M60: =(COUNTIFS(集計用!$G:$G, "*, "&$C60&", *",集計用!$AE:$AE,"56-60")+COUNTIFS(集計用!$G:$G, "*, "&$C60&", *",集計用!$AE:$AE,"61-65"))/テーブル2[[#This Row],[n=]]*100 -> 0 | N60: =COUNTIFS(集計用!$G:$G,"*, "&$C60&", *",集計用!$AE:$AE,"無回答")/テーブル2[[#This Row],[n=]]*100 -> 0
A61: NA | B61: =(COUNTIFS(集計用!$G:$G,"*, "&$C61&",*")) -> 1 | C61: おなべ | D61: =テーブル2[[#This Row],[n=]]/443*100 -> 0.22573363 | E61: =(COUNTIFS(集計用!$G:$G, "*, "&$C61&", *",集計用!$AE:$AE,"11-15")+COUNTIFS(集計用!$G:$G, "*, "&$C61&", *",集計用!$AE:$AE,"16-20"))/テーブル2[[#This Row],[n=]]*100 -> 0 | F61: =(COUNTIFS(集計用!$G:$G, "*, "&$C61&", *",集計用!$AE:$AE,"21-25"))/テーブル2[[#This Row],[n=]]*100 -> 0 | G61: =COUNTIFS(集計用!$G:$G, "*, "&$C61&", *",集計用!$AE:$AE,"26-30")/テーブル2[[#This Row],[n=]]*100 -> 100 | H61: =(COUNTIFS(集計用!$G:$G, "*, "&$C61&", *",集計用!$AE:$AE,"31-35"))/テーブル2[[#This Row],[n=]]*100 -> 0 | I61: =(COUNTIFS(集計用!$G:$G, "*, "&$C61&", *",集計用!$AE:$AE,"36-40"))/テーブル2[[#This Row],[n=]]*100 -> 0 | J61: =(COUNTIFS(集計用!$G:$G, "*, "&$C61&", *",集計用!$AE:$AE,"41-45"))/テーブル2[[#This Row],[n=]]*100 -> 0 | K61: =(COUNTIFS(集計用!$G:$G, "*, "&$C61&", *",集計用!$AE:$AE,"46-50"))/テーブル2[[#This Row],[n=]]*100 -> 0 | L61: =(COUNTIFS(集計用!$G:$G, "*, "&$C61&", *",集計用!$AE:$AE,"51-55")+COUNTIFS(集計用!$G:$G, "*, "&$C61&", *",集計用!$AE:$AE,"56-60")+COUNTIFS(集計用!$G:$G, "*, "&$C61&", *",集計用!$AE:$AE,"61-65"))/テーブル2[[#This Row],[n=]]*100 -> 0 | M61: =(COUNTIFS(集計用!$G:$G, "*, "&$C61&", *",集計用!$AE:$AE,"56-60")+COUNTIFS(集計用!$G:$G, "*, "&$C61&", *",集計用!$AE:$AE,"61-65"))/テーブル2[[#This Row],[n=]]*100 -> 0 | N61: =COUNTIFS(集計用!$G:$G,"*, "&$C61&", *",集計用!$AE:$AE,"無回答")/テーブル2[[#This Row],[n=]]*100 -> 0

Sheet A3.ジェンダーとラベル選択数
A1: 表A3：ジェンダー・ラベルおよび年齢ごとの、選択されたジェンダー・ラベルの個数
A3: cluster | B3: n= | C3: ジェンダー・ラベル | D3: 全回答者 | E3: 16-20 | F3: 21-25 | G3: 26-30 | H3: 31-35 | I3: 36-40 | J3: 41-45 | K3: 46-50 | L3: 51-55 | M3: 56+ | N3: 無回答
A4: 0 | B4: =(COUNTA(集計用!$G:$G)-1) -> 443 | C4: 全回答者 | D4: =(SUM(集計用!$AI:$AI))/テーブル3[[#This Row],[n=]] -> 4.5349887 | E4: =(SUMIFS(集計用!$AI:$AI,集計用!$AE:$AE,"11-15")+SUMIFS(集計用!$AI:$AI,集計用!$AE:$AE,"16-20"))/(COUNTIFS(集計用!$AE:$AE,"11-15")+COUNTIFS(集計用!$AE:$AE,"16-20")) -> 3.877551 | F4: =(SUMIFS(集計用!$AI:$AI,集計用!$AE:$AE,F$3))/COUNTIFS(集計用!$AE:$AE,F$3) -> 5.1034483 | G4: =(SUMIFS(集計用!$AI:$AI,集計用!$AE:$AE,G$3))/COUNTIFS(集計用!$AE:$AE,G$3) -> 4.4772727 | H4: =(SUMIFS(集計用!$AI:$AI,集計用!$AE:$AE,H$3))/COUNTIFS(集計用!$AE:$AE,H$3) -> 4.7012987 | I4: =(SUMIFS(集計用!$AI:$AI,集計用!$AE:$AE,I$3))/COUNTIFS(集計用!$AE:$AE,I$3) -> 3.9411765 | J4: =(SUMIFS(集計用!$AI:$AI,集計用!$AE:$AE,J$3))/COUNTIFS(集計用!$AE:$AE,J$3) -> 4 | K4: =(SUMIFS(集計用!$AI:$AI,集計用!$AE:$AE,K$3))/COUNTIFS(集計用!$AE:$AE,K$3) -> 3.7083333 | L4: =(SUMIFS(集計用!$AI:$AI,集計用!$AE:$AE,L$3))/COUNTIFS(集計用!$AE:$AE,L$3) -> 4.0909091 | M4: =(SUMIFS(集計用!$AI:$AI,集計用!$AE:$AE,"56-60")+SUMIFS(集計用!$AI:$AI,集計用!$AE:$AE,"61-65"))/(COUNTIFS(集計用!$AE:$AE,"56-60")+COUNTIFS(集計用!$AE:$AE,"61-65")) -> 6.5 | N4: =(SUMIFS(集計用!$AI:$AI,集計用!$AE:$AE,N$3))/COUNTIFS(集計用!$AE:$AE,N$3) -> 1
A5: 1 | B5: =(COUNTIFS(集計用!$G:$G,"*, "&$C5&",*")) -> 256 | C5: ノンバイナリー | D5: =SUMIFS(集計用!$AI:$AI,集計用!$G:$G,"*, "&$C5&", *")/テーブル3[[#This Row],[n=]] -> 5.34375 | E5: =(SUMIFS(集計用!$AI:$AI,集計用!$AE:$AE,"11-15")+SUMIFS(集計用!$AI:$AI,集計用!$AE:$AE,"16-20"))/(COUNTIFS(集計用!$AE:$AE,"11-15")+COUNTIFS(集計用!$AE:$AE,"16-20")) -> 3.877551 | F5: =(SUMIFS(集計用!$AI:$AI, 集計用!$G:$G, "*, "&$C5&", *",集計用!$AE:$AE,F$3))/COUNTIFS(集計用!$G:$G, "*, "&$C5&", *",集計用!$AE:$AE,F$3) -> 5.5342466 | G5: =(SUMIFS(集計用!$AI:$AI, 集計用!$G:$G, "*, "&$C5&", *",集計用!$AE:$AE,G$3))/COUNTIFS(集計用!$G:$G, "*, "&$C5&", *",集計用!$AE:$AE,G$3) -> 4.8214286 | H5: =(SUMIFS(集計用!$AI:$AI, 集計用!$G:$G, "*, "&$C5&", *",集計用!$AE:$AE,H$3))/COUNTIFS(集計用!$G:$G, "*, "&$C5&", *",集計用!$AE:$AE,H$3) -> 5.627907 | I5: =(SUMIFS(集計用!$AI:$AI, 集計用!$G:$G, "*, "&$C5&", *",集計用!$AE:$AE,I$3))/COUNTIFS(集計用!$G:$G, "*, "&$C5&", *",集計用!$AE:$AE,I$3) -> 5.7368421 | J5: =(SUMIFS(集計用!$AI:$AI, 集計用!$G:$G, "*, "&$C5&", *",集計用!$AE:$AE,J$3))/COUNTIFS(集計用!$G:$G, "*, "&$C5&", *",集計用!$AE:$AE,J$3) -> 4.4375 | K5: =(SUMIFS(集計用!$AI:$AI, 集計用!$G:$G, "*, "&$C5&", *",集計用!$AE:$AE,K$3))/COUNTIFS(集計用!$G:$G, "*, "&$C5&", *",集計用!$AE:$AE,K$3) -> 5.4285714 | L5: =(SUMIFS(集計用!$AI:$AI, 集計用!$G:$G, "*, "&$C5&", *",集計用!$AE:$AE,L$3))/COUNTIFS(集計用!$G:$G, "*, "&$C5&", *",集計用!$AE:$AE,L$3) -> 6.1666667 | M5: =(SUMIFS(集計用!$AI:$AI, 集計用!$G:$G, "*, "&$C5&", *",集計用!$AE:$AE,"56-60")+SUMIFS(集計用!$AI:$AI, 集計用!$G:$G, "*, "&$C5&", *",集計用!$AE:$AE,"61-65"))/(COUNTIFS(集計用!$G:$G, "*, "&$C5&", *",集計用!$AE:$AE,"56-60")+COUNTIFS(集計用!$G:$G, "*, "&$C5&", *",集計用!$AE:$AE,"61-65")) -> 8.8571429 | N5: =(SUMIFS(集計用!$AI:$AI, 集計用!$G:$G, "*, "&$C5&", *",集計用!$AE:$AE,N$3))/COUNTIFS(集計用!$G:$G, "*, "&$C5&", *",集計用!$AE:$AE,N$3) -> #DIV/0!
A6: 1 | B6: =(COUNTIFS(集計用!$G:$G,"*, "&$C6&",*")) -> 144 | C6: クィア／Queer | D6: =SUMIFS(集計用!$AI:$AI,集計用!$G:$G,"*, "&$C6&", *")/テーブル3[[#This Row],[n=]] -> 6.5694444 | E6: =(SUMIFS(集計用!$AI:$AI,集計用!$AE:$AE,"11-15")+SUMIFS(集計用!$AI:$AI,集計用!$AE:$AE,"16-20"))/(COUNTIFS(集計用!$AE:$AE,"11-15")+COUNTIFS(集計用!$AE:$AE,"16-20")) -> 3.877551 | F6: =(SUMIFS(集計用!$AI:$AI, 集計用!$G:$G, "*, "&$C6&", *",集計用!$AE:$AE,F$3))/COUNTIFS(集計用!$G:$G, "*, "&$C6&", *",集計用!$AE:$AE,F$3) -> 6.8846154 | G6: =(SUMIFS(集計用!$AI:$AI, 集計用!$G:$G, "*, "&$C6&", *",集計用!$AE:$AE,G$3))/COUNTIFS(集計用!$G:$G, "*, "&$C6&", *",集計用!$AE:$AE,G$3) -> 5.5333333 | H6: =(SUMIFS(集計用!$AI:$AI, 集計用!$G:$G, "*, "&$C6&", *",集計用!$AE:$AE,H$3))/COUNTIFS(集計用!$G:$G, "*, "&$C6&", *",集計用!$AE:$AE,H$3) -> 7.047619 | I6: =(SUMIFS(集計用!$AI:$AI, 集計用!$G:$G, "*, "&$C6&", *",集計用!$AE:$AE,I$3))/COUNTIFS(集計用!$G:$G, "*, "&$C6&", *",集計用!$AE:$AE,I$3) -> 6 | J6: =(SUMIFS(集計用!$AI:$AI, 集計用!$G:$G, "*, "&$C6&", *",集計用!$AE:$AE,J$3))/COUNTIFS(集計用!$G:$G, "*, "&$C6&", *",集計用!$AE:$AE,J$3) -> 6.375 | K6: =(SUMIFS(集計用!$AI:$AI, 集計用!$G:$G, "*, "&$C6&", *",集計用!$AE:$AE,K$3))/COUNTIFS(集計用!$G:$G, "*, "&$C6&", *",集計用!$AE:$AE,K$3) -> 5.6666667 | L6: =(SUMIFS(集計用!$AI:$AI, 集計用!$G:$G, "*, "&$C6&", *",集計用!$AE:$AE,L$3))/COUNTIFS(集計用!$G:$G, "*, "&$C6&", *",集計用!$AE:$AE,L$3) -> 9 | M6: =(SUMIFS(集計用!$AI:$AI, 集計用!$G:$G, "*, "&$C6&", *",集計用!$AE:$AE,"56-60")+SUMIFS(集計用!$AI:$AI, 集計用!$G:$G, "*, "&$C6&", *",集計用!$AE:$AE,"61-65"))/(COUNTIFS(集計用!$G:$G, "*, "&$C6&", *",集計用!$AE:$AE,"56-60")+COUNTIFS(集計用!$G:$G, "*, "&$C6&", *",集計用!$AE:$AE,"61-65")) -> 8.3333333 | N6: =(SUMIFS(集計用!$AI:$AI, 集計用!$G:$G, "*, "&$C6&", *",集計用!$AE:$AE,N$3))/COUNTIFS(集計用!$G:$G, "*, "&$C6&", *",集計用!$AE:$AE,N$3) -> #DIV/0!
A7: 2 | B7: =(COUNTIFS(集計用!$G:$G,"*, "&$C7&",*")) -> 121 | C7: Xジェンダー | D7: =SUMIFS(集計用!$AI:$AI,集計用!$G:$G,"*, "&$C7&", *")/テーブル3[[#This Row],[n=]] -> 6.553719 | E7: =(SUMIFS(集計用!$AI:$AI,集計用!$AE:$AE,"11-15")+SUMIFS(集計用!$AI:$AI,集計用!$AE:$AE,"16-20"))/(COUNTIFS(集計用!$AE:$AE,"11-15")+COUNTIFS(集計用!$AE:$AE,"16-20")) -> 3.877551 | F7: =(SUMIFS(集計用!$AI:$AI, 集計用!$G:$G, "*, "&$C7&", *",集計用!$AE:$AE,F$3))/COUNTIFS(集計用!$G:$G, "*, "&$C7&", *",集計用!$AE:$AE,F$3) -> 7.3939394 | G7: =(SUMIFS(集計用!$AI:$AI, 集計用!$G:$G, "*, "&$C7&", *",集計用!$AE:$AE,G$3))/COUNTIFS(集計用!$G:$G, "*, "&$C7&", *",集計用!$AE:$AE,G$3) -> 5.5 | H7: =(SUMIFS(集計用!$AI:$AI, 集計用!$G:$G, "*, "&$C7&", *",集計用!$AE:$AE,H$3))/COUNTIFS(集計用!$G:$G, "*, "&$C7&", *",集計用!$AE:$AE,H$3) -> 6.2272727 | I7: =(SUMIFS(集計用!$AI:$AI, 集計用!$G:$G, "*, "&$C7&", *",集計用!$AE:$AE,I$3))/COUNTIFS(集計用!$G:$G, "*, "&$C7&", *",集計用!$AE:$AE,I$3) -> 8.4444444 | J7: =(SUMIFS(集計用!$AI:$AI, 集計用!$G:$G, "*, "&$C7&", *",集計用!$AE:$AE,J$3))/COUNTIFS(集計用!$G:$G, "*, "&$C7&", *",集計用!$AE:$AE,J$3) -> 5.1666667 | K7: =(SUMIFS(集計用!$AI:$AI, 集計用!$G:$G, "*, "&$C7&", *",集計用!$AE:$AE,K$3))/COUNTIFS(集計用!$G:$G, "*, "&$C7&", *",集計用!$AE:$AE,K$3) -> 6.4 | L7: =(SUMIFS(集計用!$AI:$AI, 集計用!$G:$G, "*, "&$C7&", *",集計用!$AE:$AE,L$3))/COUNTIFS(集計用!$G:$G, "*, "&$C7&", *",集計用!$AE:$AE,L$3) -> 7.6666667 | M7: =(SUMIFS(集計用!$AI:$AI, 集計用!$G:$G, "*, "&$C7&", *",集計用!$AE:$AE,"56-60")+SUMIFS(集計用!$AI:$AI, 集計用!$G:$G, "*, "&$C7&", *",集計用!$AE:$AE,"61-65"))/(COUNTIFS(集計用!$G:$G, "*, "&$C7&", *",集計用!$AE:$AE,"56-60")+COUNTIFS(集計用!$G:$G, "*, "&$C7&", *",集計用!$AE:$AE,"61-65")) -> 9.5 | N7: =(SUMIFS(集計用!$AI:$AI, 集計用!$G:$G, "*, "&$C7&", *",集計用!$AE:$AE,N$3))/COUNTIFS(集計用!$G:$G, "*, "&$C7&", *",集計用!$AE:$AE,N$3) -> #DIV/0!
A8: 1 | B8: =(COUNTIFS(集計用!$G:$G,"*, "&$C8&",*")) -> 86 | C8: クエスチョニング | D8: =SUMIFS(集計用!$AI:$AI,集計用!$G:$G,"*, "&$C8&", *")/テーブル3[[#This Row],[n=]] -> 6.8953488 | E8: =(SUMIFS(集計用!$AI:$AI,集計用!$AE:$AE,"11-15")+SUMIFS(集計用!$AI:$AI,集計用!$AE:$AE,"16-20"))/(COUNTIFS(集計用!$AE:$AE,"11-15")+COUNTIFS(集計用!$AE:$AE,"16-20")) -> 3.877551 | F8: =(SUMIFS(集計用!$AI:$AI, 集計用!$G:$G, "*, "&$C8&", *",集計用!$AE:$AE,F$3))/COUNTIFS(集計用!$G:$G, "*, "&$C8&", *",集計用!$AE:$AE,F$3) -> 7.6896552 | G8: =(SUMIFS(集計用!$AI:$AI, 集計用!$G:$G, "*, "&$C8&", *",集計用!$AE:$AE,G$3))/COUNTIFS(集計用!$G:$G, "*, "&$C8&", *",集計用!$AE:$AE,G$3) -> 5.7058824 | H8: =(SUMIFS(集計用!$AI:$AI, 集計用!$G:$G, "*, "&$C8&", *",集計用!$AE:$AE,H$3))/COUNTIFS(集計用!$G:$G, "*, "&$C8&", *",集計用!$AE:$AE,H$3) -> 7.2666667 | I8: =(SUMIFS(集計用!$AI:$AI, 集計用!$G:$G, "*, "&$C8&", *",集計用!$AE:$AE,I$3))/COUNTIFS(集計用!$G:$G, "*, "&$C8&", *",集計用!$AE:$AE,I$3) -> 6 | J8: =(SUMIFS(集計用!$AI:$AI, 集計用!$G:$G, "*, "&$C8&", *",集計用!$AE:$AE,J$3))/COUNTIFS(集計用!$G:$G, "*, "&$C8&", *",集計用!$AE:$AE,J$3) -> 5.5 | K8: =(SUMIFS(集計用!$AI:$AI, 集計用!$G:$G, "*, "&$C8&", *",集計用!$AE:$AE,K$3))/COUNTIFS(集計用!$G:$G, "*, "&$C8&", *",集計用!$AE:$AE,K$3) -> #DIV/0! | L8: =(SUMIFS(集計用!$AI:$AI, 集計用!$G:$G, "*, "&$C8&", *",集計用!$AE:$AE,L$3))/COUNTIFS(集計用!$G:$G, "*, "&$C8&", *",集計用!$AE:$AE,L$3) -> 7.25 | M8: =(SUMIFS(集計用!$AI:$AI, 集計用!$G:$G, "*, "&$C8&", *",集計用!$AE:$AE,"56-60")+SUMIFS(集計用!$AI:$AI, 集計用!$G:$G, "*, "&$C8&", *",集計用!$AE:$AE,"61-65"))/(COUNTIFS(集計用!$G:$G, "*, "&$C8&", *",集計用!$AE:$AE,"56-60")+COUNTIFS(集計用!$G:$G, "*, "&$C8&", *",集計用!$AE:$AE,"61-65")) -> 10 | N8: =(SUMIFS(集計用!$AI:$AI, 集計用!$G:$G, "*, "&$C8&", *",集計用!$AE:$AE,N$3))/COUNTIFS(集計用!$G:$G, "*, "&$C8&", *",集計用!$AE:$AE,N$3) -> #DIV/0!
A9: 3 | B9: =(COUNTIFS(集計用!$G:$G,"*, "&$C9&",*")) -> 86 | C9: 無性 | D9: =SUMIFS(集計用!$AI:$AI,集計用!$G:$G,"*, "&$C9&", *")/テーブル3[[#This Row],[n=]] -> 6.3255814 | E9: =(SUMIFS(集計用!$AI:$AI,集計用!$AE:$AE,"11-15")+SUMIFS(集計用!$AI:$AI,集計用!$AE:$AE,"16-20"))/(COUNTIFS(集計用!$AE:$AE,"11-15")+COUNTIFS(集計用!$AE:$AE,"16-20")) -> 3.877551 | F9: =(SUMIFS(集計用!$AI:$AI, 集計用!$G:$G, "*, "&$C9&", *",集計用!$AE:$AE,F$3))/COUNTIFS(集計用!$G:$G, "*, "&$C9&", *",集計用!$AE:$AE,F$3) -> 7.9047619 | G9: =(SUMIFS(集計用!$AI:$AI, 集計用!$G:$G, "*, "&$C9&", *",集計用!$AE:$AE,G$3))/COUNTIFS(集計用!$G:$G, "*, "&$C9&", *",集計用!$AE:$AE,G$3) -> 5.35 | H9: =(SUMIFS(集計用!$AI:$AI, 集計用!$G:$G, "*, "&$C9&", *",集計用!$AE:$AE,H$3))/COUNTIFS(集計用!$G:$G, "*, "&$C9&", *",集計用!$AE:$AE,H$3) -> 5.6 | I9: =(SUMIFS(集計用!$AI:$AI, 集計用!$G:$G, "*, "&$C9&", *",集計用!$AE:$AE,I$3))/COUNTIFS(集計用!$G:$G, "*, "&$C9&", *",集計用!$AE:$AE,I$3) -> 7 | J9: =(SUMIFS(集計用!$AI:$AI, 集計用!$G:$G, "*, "&$C9&", *",集計用!$AE:$AE,J$3))/COUNTIFS(集計用!$G:$G, "*, "&$C9&", *",集計用!$AE:$AE,J$3) -> 5.6666667 | K9: =(SUMIFS(集計用!$AI:$AI, 集計用!$G:$G, "*, "&$C9&", *",集計用!$AE:$AE,K$3))/COUNTIFS(集計用!$G:$G, "*, "&$C9&", *",集計用!$AE:$AE,K$3) -> 6.4 | L9: =(SUMIFS(集計用!$AI:$AI, 集計用!$G:$G, "*, "&$C9&", *",集計用!$AE:$AE,L$3))/COUNTIFS(集計用!$G:$G, "*, "&$C9&", *",集計用!$AE:$AE,L$3) -> 5.5 | M9: =(SUMIFS(集計用!$AI:$AI, 集計用!$G:$G, "*, "&$C9&", *",集計用!$AE:$AE,"56-60")+SUMIFS(集計用!$AI:$AI, 集計用!$G:$G, "*, "&$C9&", *",集計用!$AE:$AE,"61-65"))/(COUNTIFS(集計用!$G:$G, "*, "&$C9&", *",集計用!$AE:$AE,"56-60")+COUNTIFS(集計用!$G:$G, "*, "&$C9&", *",集計用!$AE:$AE,"61-65")) -> 3.5 | N9: =(SUMIFS(集計用!$AI:$AI, 集計用!$G:$G, "*, "&$C9&", *",集計用!$AE:$AE,N$3))/COUNTIFS(集計用!$G:$G, "*, "&$C9&", *",集計用!$AE:$AE,N$3) -> #DIV/0!
A10: 4 | B10: =(COUNTIFS(集計用!$G:$G,"*, "&$C10&",*")) -> 75 | C10: （ジェンダー・）フルイド／（ジェンダー・）フリュイド／（ジェンダー・）フルイッド | D10: =SUMIFS(集計用!$AI:$AI,集計用!$G:$G,"*, "&$C10&", *")/テーブル3[[#This Row],[n=]] -> 7.6 | E10: =(SUMIFS(集計用!$AI:$AI,集計用!$AE:$AE,"11-15")+SUMIFS(集計用!$AI:$AI,集計用!$AE:$AE,"16-20"))/(COUNTIFS(集計用!$AE:$AE,"11-15")+COUNTIFS(集計用!$AE:$AE,"16-20")) -> 3.877551 | F10: =(SUMIFS(集計用!$AI:$AI, 集計用!$G:$G, "*, "&$C10&", *",集計用!$AE:$AE,F$3))/COUNTIFS(集計用!$G:$G, "*, "&$C10&", *",集計用!$AE:$AE,F$3) -> 7.8148148 | G10: =(SUMIFS(集計用!$AI:$AI, 集計用!$G:$G, "*, "&$C10&", *",集計用!$AE:$AE,G$3))/COUNTIFS(集計用!$G:$G, "*, "&$C10&", *",集計用!$AE:$AE,G$3) -> 4.9411765 | H10: =(SUMIFS(集計用!$AI:$AI, 集計用!$G:$G, "*, "&$C10&", *",集計用!$AE:$AE,H$3))/COUNTIFS(集計用!$G:$G, "*, "&$C10&", *",集計用!$AE:$AE,H$3) -> 9.125 | I10: =(SUMIFS(集計用!$AI:$AI, 集計用!$G:$G, "*, "&$C10&", *",集計用!$AE:$AE,I$3))/COUNTIFS(集計用!$G:$G, "*, "&$C10&", *",集計用!$AE:$AE,I$3) -> 11 | J10: =(SUMIFS(集計用!$AI:$AI, 集計用!$G:$G, "*, "&$C10&", *",集計用!$AE:$AE,J$3))/COUNTIFS(集計用!$G:$G, "*, "&$C10&", *",集計用!$AE:$AE,J$3) -> 8 | K10: =(SUMIFS(集計用!$AI:$AI, 集計用!$G:$G, "*, "&$C10&", *",集計用!$AE:$AE,K$3))/COUNTIFS(集計用!$G:$G, "*, "&$C10&", *",集計用!$AE:$AE,K$3) -> 3.5 | L10: =(SUMIFS(集計用!$AI:$AI, 集計用!$G:$G, "*, "&$C10&", *",集計用!$AE:$AE,L$3))/COUNTIFS(集計用!$G:$G, "*, "&$C10&", *",集計用!$AE:$AE,L$3) -> #DIV/0! | M10: =(SUMIFS(集計用!$AI:$AI, 集計用!$G:$G, "*, "&$C10&", *",集計用!$AE:$AE,"56-60")+SUMIFS(集計用!$AI:$AI, 集計用!$G:$G, "*, "&$C10&", *",集計用!$AE:$AE,"61-65"))/(COUNTIFS(集計用!$G:$G, "*, "&$C10&", *",集計用!$AE:$AE,"56-60")+COUNTIFS(集計用!$G:$G, "*, "&$C10&", *",集計用!$AE:$AE,"61-65")) -> 11.5 | N10: =(SUMIFS(集計用!$AI:$AI, 集計用!$G:$G, "*, "&$C10&", *",集計用!$AE:$AE,N$3))/COUNTIFS(集計用!$G:$G, "*, "&$C10&", *",集計用!$AE:$AE,N$3) -> #DIV/0!
A11: 1 | B11: =(COUNTIFS(集計用!$G:$G,"*, "&$C11&",*")) -> 74 | C11: ジェンダークィア | D11: =SUMIFS(集計用!$AI:$AI,集計用!$G:$G,"*, "&$C11&", *")/テーブル3[[#This Row],[n=]] -> 7.6351351 | E11: =(SUMIFS(集計用!$AI:$AI,集計用!$AE:$AE,"11-15")+SUMIFS(集計用!$AI:$AI,集計用!$AE:$AE,"16-20"))/(COUNTIFS(集計用!$AE:$AE,"11-15")+COUNTIFS(集計用!$AE:$AE,"16-20")) -> 3.877551 | F11: =(SUMIFS(集計用!$AI:$AI, 集計用!$G:$G, "*, "&$C11&", *",集計用!$AE:$AE,F$3))/COUNTIFS(集計用!$G:$G, "*, "&$C11&", *",集計用!$AE:$AE,F$3) -> 8.6296296 | G11: =(SUMIFS(集計用!$AI:$AI, 集計用!$G:$G, "*, "&$C11&", *",集計用!$AE:$AE,G$3))/COUNTIFS(集計用!$G:$G, "*, "&$C11&", *",集計用!$AE:$AE,G$3) -> 6.25 | H11: =(SUMIFS(集計用!$AI:$AI, 集計用!$G:$G, "*, "&$C11&", *",集計用!$AE:$AE,H$3))/COUNTIFS(集計用!$G:$G, "*, "&$C11&", *",集計用!$AE:$AE,H$3) -> 7.5454545 | I11: =(SUMIFS(集計用!$AI:$AI, 集計用!$G:$G, "*, "&$C11&", *",集計用!$AE:$AE,I$3))/COUNTIFS(集計用!$G:$G, "*, "&$C11&", *",集計用!$AE:$AE,I$3) -> 9.2 | J11: =(SUMIFS(集計用!$AI:$AI, 集計用!$G:$G, "*, "&$C11&", *",集計用!$AE:$AE,J$3))/COUNTIFS(集計用!$G:$G, "*, "&$C11&", *",集計用!$AE:$AE,J$3) -> 6.3333333 | K11: =(SUMIFS(集計用!$AI:$AI, 集計用!$G:$G, "*, "&$C11&", *",集計用!$AE:$AE,K$3))/COUNTIFS(集計用!$G:$G, "*, "&$C11&", *",集計用!$AE:$AE,K$3) -> 4.6666667 | L11: =(SUMIFS(集計用!$AI:$AI, 集計用!$G:$G, "*, "&$C11&", *",集計用!$AE:$AE,L$3))/COUNTIFS(集計用!$G:$G, "*, "&$C11&", *",集計用!$AE:$AE,L$3) -> #DIV/0! | M11: =(SUMIFS(集計用!$AI:$AI, 集計用!$G:$G, "*, "&$C11&", *",集計用!$AE:$AE,"56-60")+SUMIFS(集計用!$AI:$AI, 集計用!$G:$G, "*, "&$C11&", *",集計用!$AE:$AE,"61-65"))/(COUNTIFS(集計用!$G:$G, "*, "&$C11&", *",集計用!$AE:$AE,"56-60")+COUNTIFS(集計用!$G:$G, "*, "&$C11&", *",集計用!$AE:$AE,"61-65")) -> 7.8 | N11: =(SUMIFS(集計用!$AI:$AI, 集計用!$G:$G, "*, "&$C11&", *",集計用!$AE:$AE,N$3))/COUNTIFS(集計用!$G:$G, "*, "&$C11&", *",集計用!$AE:$AE,N$3) -> #DIV/0!
A12: 3 | B12: =(COUNTIFS(集計用!$G:$G,"*, "&$C12&",*")) -> 71 | C12: Aジェンダー／エイジェンダー／アジェンダー／agender | D12: =SUMIFS(集計用!$AI:$AI,集計用!$G:$G,"*, "&$C12&", *")/テーブル3[[#This Row],[n=]] -> 6.7746479 | E12: =(SUMIFS(集計用!$AI:$AI,集計用!$AE:$AE,"11-15")+SUMIFS(集計用!$AI:$AI,集計用!$AE:$AE,"16-20"))/(COUNTIFS(集計用!$AE:$AE,"11-15")+COUNTIFS(集計用!$AE:$AE,"16-20")) -> 3.877551 | F12: =(SUMIFS(集計用!$AI:$AI, 集計用!$G:$G, "*, "&$C12&", *",集計用!$AE:$AE,F$3))/COUNTIFS(集計用!$G:$G, "*, "&$C12&", *",集計用!$AE:$AE,F$3) -> 8.1 | G12: =(SUMIFS(集計用!$AI:$AI, 集計用!$G:$G, "*, "&$C12&", *",集計用!$AE:$AE,G$3))/COUNTIFS(集計用!$G:$G, "*, "&$C12&", *",集計用!$AE:$AE,G$3) -> 5.8666667 | H12: =(SUMIFS(集計用!$AI:$AI, 集計用!$G:$G, "*, "&$C12&", *",集計用!$AE:$AE,H$3))/COUNTIFS(集計用!$G:$G, "*, "&$C12&", *",集計用!$AE:$AE,H$3) -> 6.9230769 | I12: =(SUMIFS(集計用!$AI:$AI, 集計用!$G:$G, "*, "&$C12&", *",集計用!$AE:$AE,I$3))/COUNTIFS(集計用!$G:$G, "*, "&$C12&", *",集計用!$AE:$AE,I$3) -> 7.3333333 | J12: =(SUMIFS(集計用!$AI:$AI, 集計用!$G:$G, "*, "&$C12&", *",集計用!$AE:$AE,J$3))/COUNTIFS(集計用!$G:$G, "*, "&$C12&", *",集計用!$AE:$AE,J$3) -> 6 | K12: =(SUMIFS(集計用!$AI:$AI, 集計用!$G:$G, "*, "&$C12&", *",集計用!$AE:$AE,K$3))/COUNTIFS(集計用!$G:$G, "*, "&$C12&", *",集計用!$AE:$AE,K$3) -> 3 | L12: =(SUMIFS(集計用!$AI:$AI, 集計用!$G:$G, "*, "&$C12&", *",集計用!$AE:$AE,L$3))/COUNTIFS(集計用!$G:$G, "*, "&$C12&", *",集計用!$AE:$AE,L$3) -> 4.6666667 | M12: =(SUMIFS(集計用!$AI:$AI, 集計用!$G:$G, "*, "&$C12&", *",集計用!$AE:$AE,"56-60")+SUMIFS(集計用!$AI:$AI, 集計用!$G:$G, "*, "&$C12&", *",集計用!$AE:$AE,"61-65"))/(COUNTIFS(集計用!$G:$G, "*, "&$C12&", *",集計用!$AE:$AE,"56-60")+COUNTIFS(集計用!$G:$G, "*, "&$C12&", *",集計用!$AE:$AE,"61-65")) -> 18 | N12: =(SUMIFS(集計用!$AI:$AI, 集計用!$G:$G, "*, "&$C12&", *",集計用!$AE:$AE,N$3))/COUNTIFS(集計用!$G:$G, "*, "&$C12&", *",集計用!$AE:$AE,N$3) -> #DIV/0!
A13: 1 | B13: =(COUNTIFS(集計用!$G:$G,"*, "&$C13&",*")) -> 71 | C13: 不明／わからない | D13: =SUMIFS(集計用!$AI:$AI,集計用!$G:$G,"*, "&$C13&", *")/テーブル3[[#This Row],[n=]] -> 6.7183099 | E13: =(SUMIFS(集計用!$AI:$AI,集計用!$AE:$AE,"11-15")+SUMIFS(集計用!$AI:$AI,集計用!$AE:$AE,"16-20"))/(COUNTIFS(集計用!$AE:$AE,"11-15")+COUNTIFS(集計用!$AE:$AE,"16-20")) -> 3.877551 | F13: =(SUMIFS(集計用!$AI:$AI, 集計用!$G:$G, "*, "&$C13&", *",集計用!$AE:$AE,F$3))/COUNTIFS(集計用!$G:$G, "*, "&$C13&", *",集計用!$AE:$AE,F$3) -> 8.2727273 | G13: =(SUMIFS(集計用!$AI:$AI, 集計用!$G:$G, "*, "&$C13&", *",集計用!$AE:$AE,G$3))/COUNTIFS(集計用!$G:$G, "*, "&$C13&", *",集計用!$AE:$AE,G$3) -> 5.8235294 | H13: =(SUMIFS(集計用!$AI:$AI, 集計用!$G:$G, "*, "&$C13&", *",集計用!$AE:$AE,H$3))/COUNTIFS(集計用!$G:$G, "*, "&$C13&", *",集計用!$AE:$AE,H$3) -> 7.1428571 | I13: =(SUMIFS(集計用!$AI:$AI, 集計用!$G:$G, "*, "&$C13&", *",集計用!$AE:$AE,I$3))/COUNTIFS(集計用!$G:$G, "*, "&$C13&", *",集計用!$AE:$AE,I$3) -> 1.5 | J13: =(SUMIFS(集計用!$AI:$AI, 集計用!$G:$G, "*, "&$C13&", *",集計用!$AE:$AE,J$3))/COUNTIFS(集計用!$G:$G, "*, "&$C13&", *",集計用!$AE:$AE,J$3) -> 4 | K13: =(SUMIFS(集計用!$AI:$AI, 集計用!$G:$G, "*, "&$C13&", *",集計用!$AE:$AE,K$3))/COUNTIFS(集計用!$G:$G, "*, "&$C13&", *",集計用!$AE:$AE,K$3) -> 4.6666667 | L13: =(SUMIFS(集計用!$AI:$AI, 集計用!$G:$G, "*, "&$C13&", *",集計用!$AE:$AE,L$3))/COUNTIFS(集計用!$G:$G, "*, "&$C13&", *",集計用!$AE:$AE,L$3) -> 9 | M13: =(SUMIFS(集計用!$AI:$AI, 集計用!$G:$G, "*, "&$C13&", *",集計用!$AE:$AE,"56-60")+SUMIFS(集計用!$AI:$AI, 集計用!$G:$G, "*, "&$C13&", *",集計用!$AE:$AE,"61-65"))/(COUNTIFS(集計用!$G:$G, "*, "&$C13&", *",集計用!$AE:$AE,"56-60")+COUNTIFS(集計用!$G:$G, "*, "&$C13&", *",集計用!$AE:$AE,"61-65")) -> 8 | N13: =(SUMIFS(集計用!$AI:$AI, 集計用!$G:$G, "*, "&$C13&", *",集計用!$AE:$AE,N$3))/COUNTIFS(集計用!$G:$G, "*, "&$C13&", *",集計用!$AE:$AE,N$3) -> #DIV/0!
A14: 2 | B14: =(COUNTIFS(集計用!$G:$G,"*, "&$C14&",*")) -> 69 | C14: X | D14: =SUMIFS(集計用!$AI:$AI,集計用!$G:$G,"*, "&$C14&", *")/テーブル3[[#This Row],[n=]] -> 7.1449275 | E14: =(SUMIFS(集計用!$AI:$AI,集計用!$AE:$AE,"11-15")+SUMIFS(集計用!$AI:$AI,集計用!$AE:$AE,"16-20"))/(COUNTIFS(集計用!$AE:$AE,"11-15")+COUNTIFS(集計用!$AE:$AE,"16-20")) -> 3.877551 | F14: =(SUMIFS(集計用!$AI:$AI, 集計用!$G:$G, "*, "&$C14&", *",集計用!$AE:$AE,F$3))/COUNTIFS(集計用!$G:$G, "*, "&$C14&", *",集計用!$AE:$AE,F$3) -> 9.625 | G14: =(SUMIFS(集計用!$AI:$AI, 集計用!$G:$G, "*, "&$C14&", *",集計用!$AE:$AE,G$3))/COUNTIFS(集計用!$G:$G, "*, "&$C14&", *",集計用!$AE:$AE,G$3) -> 6.3125 | H14: =(SUMIFS(集計用!$AI:$AI, 集計用!$G:$G, "*, "&$C14&", *",集計用!$AE:$AE,H$3))/COUNTIFS(集計用!$G:$G, "*, "&$C14&", *",集計用!$AE:$AE,H$3) -> 6.1538462 | I14: =(SUMIFS(集計用!$AI:$AI, 集計用!$G:$G, "*, "&$C14&", *",集計用!$AE:$AE,I$3))/COUNTIFS(集計用!$G:$G, "*, "&$C14&", *",集計用!$AE:$AE,I$3) -> 7.5 | J14: =(SUMIFS(集計用!$AI:$AI, 集計用!$G:$G, "*, "&$C14&", *",集計用!$AE:$AE,J$3))/COUNTIFS(集計用!$G:$G, "*, "&$C14&", *",集計用!$AE:$AE,J$3) -> 6 | K14: =(SUMIFS(集計用!$AI:$AI, 集計用!$G:$G, "*, "&$C14&", *",集計用!$AE:$AE,K$3))/COUNTIFS(集計用!$G:$G, "*, "&$C14&", *",集計用!$AE:$AE,K$3) -> 7 | L14: =(SUMIFS(集計用!$AI:$AI, 集計用!$G:$G, "*, "&$C14&", *",集計用!$AE:$AE,L$3))/COUNTIFS(集計用!$G:$G, "*, "&$C14&", *",集計用!$AE:$AE,L$3) -> #DIV/0! | M14: =(SUMIFS(集計用!$AI:$AI, 集計用!$G:$G, "*, "&$C14&", *",集計用!$AE:$AE,"56-60")+SUMIFS(集計用!$AI:$AI, 集計用!$G:$G, "*, "&$C14&", *",集計用!$AE:$AE,"61-65"))/(COUNTIFS(集計用!$G:$G, "*, "&$C14&", *",集計用!$AE:$AE,"56-60")+COUNTIFS(集計用!$G:$G, "*, "&$C14&", *",集計用!$AE:$AE,"61-65")) -> 12.5 | N14: =(SUMIFS(集計用!$AI:$AI, 集計用!$G:$G, "*, "&$C14&", *",集計用!$AE:$AE,N$3))/COUNTIFS(集計用!$G:$G, "*, "&$C14&", *",集計用!$AE:$AE,N$3) -> 1
A15: 5 | B15: =(COUNTIFS(集計用!$G:$G,"*, "&$C15&",*")) -> 60 | C15: トランスジェンダー | D15: =SUMIFS(集計用!$AI:$AI,集計用!$G:$G,"*, "&$C15&", *")/テーブル3[[#This Row],[n=]] -> 8.1833333 | E15: =(SUMIFS(集計用!$AI:$AI,集計用!$AE:$AE,"11-15")+SUMIFS(集計用!$AI:$AI,集計用!$AE:$AE,"16-20"))/(COUNTIFS(集計用!$AE:$AE,"11-15")+COUNTIFS(集計用!$AE:$AE,"16-20")) -> 3.877551 | F15: =(SUMIFS(集計用!$AI:$AI, 集計用!$G:$G, "*, "&$C15&", *",集計用!$AE:$AE,F$3))/COUNTIFS(集計用!$G:$G, "*, "&$C15&", *",集計用!$AE:$AE,F$3) -> 11.153846 | G15: =(SUMIFS(集計用!$AI:$AI, 集計用!$G:$G, "*, "&$C15&", *",集計用!$AE:$AE,G$3))/COUNTIFS(集計用!$G:$G, "*, "&$C15&", *",集計用!$AE:$AE,G$3) -> 5.9333333 | H15: =(SUMIFS(集計用!$AI:$AI, 集計用!$G:$G, "*, "&$C15&", *",集計用!$AE:$AE,H$3))/COUNTIFS(集計用!$G:$G, "*, "&$C15&", *",集計用!$AE:$AE,H$3) -> 7.3333333 | I15: =(SUMIFS(集計用!$AI:$AI, 集計用!$G:$G, "*, "&$C15&", *",集計用!$AE:$AE,I$3))/COUNTIFS(集計用!$G:$G, "*, "&$C15&", *",集計用!$AE:$AE,I$3) -> 7.5 | J15: =(SUMIFS(集計用!$AI:$AI, 集計用!$G:$G, "*, "&$C15&", *",集計用!$AE:$AE,J$3))/COUNTIFS(集計用!$G:$G, "*, "&$C15&", *",集計用!$AE:$AE,J$3) -> 7 | K15: =(SUMIFS(集計用!$AI:$AI, 集計用!$G:$G, "*, "&$C15&", *",集計用!$AE:$AE,K$3))/COUNTIFS(集計用!$G:$G, "*, "&$C15&", *",集計用!$AE:$AE,K$3) -> 7 | L15: =(SUMIFS(集計用!$AI:$AI, 集計用!$G:$G, "*, "&$C15&", *",集計用!$AE:$AE,L$3))/COUNTIFS(集計用!$G:$G, "*, "&$C15&", *",集計用!$AE:$AE,L$3) -> 7.5 | M15: =(SUMIFS(集計用!$AI:$AI, 集計用!$G:$G, "*, "&$C15&", *",集計用!$AE:$AE,"56-60")+SUMIFS(集計用!$AI:$AI, 集計用!$G:$G, "*, "&$C15&", *",集計用!$AE:$AE,"61-65"))/(COUNTIFS(集計用!$G:$G, "*, "&$C15&", *",集計用!$AE:$AE,"56-60")+COUNTIFS(集計用!$G:$G, "*, "&$C15&", *",集計用!$AE:$AE,"61-65")) -> 10.75 | N15: =(SUMIFS(集計用!$AI:$AI, 集計用!$G:$G, "*, "&$C15&", *",集計用!$AE:$AE,N$3))/COUNTIFS(集計用!$G:$G, "*, "&$C15&", *",集計用!$AE:$AE,N$3) -> #DIV/0!
